Workbook

Sheet README
B2: Dataset | C2: Page Name | D2: Source
B3: County Population and Housing Timeseries, 2010 to Current Year | C3: CountyPopHousing | D3: link
B4: County Population Profiles, 1985 to Current Year | C4: CountingHousingProf | D4: link

Sheet CountyHousingProf
A1: Vintage 2022 prepared October 2023.
A2: countyfips | B2: name | C2: year | D2: totalpopulation | E2: births | F2: naturalincrease | G2: netmigration | H2: deaths | I2: totalhousingunits | J2: households | K2: householdsize | L2: householdpopulation | M2: censusbuildingpermits | N2: vacancyrate | O2: vacanthousingunits | P2: hhldpoptothuratio
A3: 000 | B3: COLORADO STATE | C3: 2020 | D3: 5784584 | E3: 62809 | F3: 20660 | G3: 29011 | H3: 42149 | I3: 2501178 | L3: 5659934 | M3: 40469 | P3: 2.2629073
A4: 001 | B4: ADAMS COUNTY | C4: 2020 | D4: 520433 | E4: 6805 | F4: 3403 | G4: 548 | H4: 3402 | I4: 187288 | L4: 515957 | M4: 4027 | P4: 2.7548855
A5: 003 | B5: ALAMOSA COUNTY | C5: 2020 | D5: 16371 | E5: 187 | F5: 28 | G5: 96 | H5: 159 | I5: 7072 | L5: 15411 | M5: 62 | P5: 2.1791572
A6: 005 | B6: ARAPAHOE COUNTY | C6: 2020 | D6: 655212 | E6: 7580 | F6: 2964 | G6: -1556 | H6: 4616 | I6: 263241 | L6: 649825 | M6: 4116 | P6: 2.4685554
A7: 007 | B7: ARCHULETA COUNTY | C7: 2020 | D7: 13428 | E7: 102 | F7: -8 | G7: 242 | H7: 110 | I7: 9537 | L7: 13330 | M7: 153 | P7: 1.3977142
A8: 009 | B8: BACA COUNTY | C8: 2020 | D8: 3478 | E8: 40 | F8: -28 | G8: -59 | H8: 68 | I8: 1972 | L8: 3424 | M8: 2 | P8: 1.7363083
A9: 011 | B9: BENT COUNTY | C9: 2020 | D9: 5477 | E9: 43 | F9: -28 | G9: -475 | H9: 71 | I9: 2136 | L9: 4071 | M9: 5 | P9: 1.9058989
A10: 013 | B10: BOULDER COUNTY | C10: 2020 | D10: 330923 | E10: 2507 | F10: 467 | G10: 1629 | H10: 2040 | I10: 141291 | L10: 315633 | M10: 1634 | P10: 2.2339215
A11: 014 | B11: BROOMFIELD COUNTY | C11: 2020 | D11: 74494 | E11: 642 | F11: 210 | G11: 1615 | H11: 432 | I11: 31463 | L11: 74013 | M11: 427 | P11: 2.3523822
A12: 015 | B12: CHAFFEE COUNTY | C12: 2020 | D12: 19478 | E12: 135 | F12: -74 | G12: 161 | H12: 209 | I12: 10993 | L12: 18247 | M12: 186 | P12: 1.6598745
A13: 017 | B13: CHEYENNE COUNTY | C13: 2020 | D13: 1744 | E13: 17 | F13: 0 | G13: -33 | H13: 17 | I13: 929 | L13: 1722 | M13: 6 | P13: 1.853606
A14: 019 | B14: CLEAR CREEK COUNTY | C14: 2020 | D14: 9397 | E14: 67 | F14: -6 | G14: -11 | H14: 73 | I14: 5688 | L14: 9315 | M14: 94 | P14: 1.6376582
... A197: 125 | B197: YUMA COUNTY | C197: 2022 | D197: 9920 | E197: 140 | F197: 45 | G197: -57 | H197: 95 | I197: 4326 | L197: 9757 | M197: 20 | P197: 2.2554323

Sheet CountyPopHousing
A1: Vintage 2022 prepared October 2023.
A2: County FIPS | B2: County | C2: Year | D2: Total Population | E2: Household Population | F2: Group Quarters Population | G2: Household Size | H2: Total Housing Units | I2: Occupied Housing Units | J2: Vacant Housing Units | K2: Vacancy Percent | L2: Household Population to Total Housing Units Ratio
A3: 0 | B3: Colorado State | C3: 2010 | D3: 5050332 | E3: 4933380 | F3: 116952 | G3: 2.5 | H3: 2205618 | I3: 1971855 | J3: 233763 | K3: 10.6 | L3: 2.2367337
A4: 1 | B4: Adams County | C4: 2010 | D4: 443711 | E4: 439684 | F4: 4027 | G4: 2.85 | H4: 163435 | I4: 154505 | J4: 8930 | K4: 5.46 | L4: 2.6902683
A5: 3 | B5: Alamosa County | C5: 2010 | D5: 15474 | E5: 14734 | F5: 740 | G5: 2.45 | H5: 6561 | I5: 6007 | J5: 554 | K5: 8.44 | L5: 2.2456943
A6: 5 | B6: Arapahoe County | C6: 2010 | D6: 574819 | E6: 569899 | F6: 4920 | G6: 2.53 | H6: 239171 | I6: 225108 | J6: 14063 | K6: 5.88 | L6: 2.3828098
A7: 7 | B7: Archuleta County | C7: 2010 | D7: 12060 | E7: 11931 | F7: 129 | G7: 2.27 | H7: 8762 | I7: 5257 | J7: 3505 | K7: 40 | L7: 1.3616754
A8: 9 | B8: Baca County | C8: 2010 | D8: 3795 | E8: 3713 | F8: 82 | G8: 2.52 | H8: 1964 | I8: 1475 | J8: 489 | K8: 24.9 | L8: 1.8905295
A9: 11 | B9: Bent County | C9: 2010 | D9: 6506 | E9: 4298 | F9: 2208 | G9: 2.49 | H9: 2111 | I9: 1728 | J9: 383 | K9: 18.14 | L9: 2.0360019
A10: 13 | B10: Boulder County | C10: 2010 | D10: 295605 | E10: 286209 | F10: 9396 | G10: 2.39 | H10: 127213 | I10: 119568 | J10: 7645 | K10: 6.01 | L10: 2.2498408
A11: 14 | B11: Broomfield County | C11: 2010 | D11: 56107 | E11: 55825 | F11: 282 | G11: 2.6 | H11: 22685 | I11: 21498 | J11: 1187 | K11: 5.23 | L11: 2.4608772
A12: 15 | B12: Chaffee County | C12: 2010 | D12: 17797 | E12: 16361 | F12: 1436 | G12: 2.15 | H12: 10030 | I12: 7595 | J12: 2435 | K12: 24.28 | L12: 1.6312064
A13: 17 | B13: Cheyenne County | C13: 2010 | D13: 1834 | E13: 1792 | F13: 42 | G13: 2.55 | H13: 868 | I13: 702 | J13: 166 | K13: 19.12 | L13: 2.0645161
A14: 19 | B14: Clear Creek County | C14: 2010 | D14: 9155 | E14: 9024 | F14: 131 | G14: 2.22 | H14: 5472 | I14: 4060 | J14: 1412 | K14: 25.8 | L14: 1.6491228
... A652: 125 | B652: Yuma County | C652: 2019 | D652: 10010 | E652: 9793 | F652: 217 | G652: 2.54 | H652: 4317 | I652: 3862 | J652: 455 | K652: 10.55 | L652: 2.2684735
A653: 0 | B653: Colorado State | C653: 2020 | D653: 5784584 | E653: 5659934 | F653: 124650 | H653: 2501178 | L653: 2.2629073
A654: 1 | B654: Adams County | C654: 2020 | D654: 520433 | E654: 515957 | F654: 4476 | H654: 187288 | L654: 2.7548855
A655: 3 | B655: Alamosa County | C655: 2020 | D655: 16371 | E655: 15411 | F655: 960 | H655: 7072 | L655: 2.1791572
A656: 5 | B656: Arapahoe County | C656: 2020 | D656: 655212 | E656: 649825 | F656: 5387 | H656: 263241 | L656: 2.4685554
A657: 7 | B657: Archuleta County | C657: 2020 | D657: 13428 | E657: 13330 | F657: 98 | H657: 9537 | L657: 1.3977142
A658: 9 | B658: Baca County | C658: 2020 | D658: 3478 | E658: 3424 | F658: 54 | H658: 1972 | L658: 1.7363083
A659: 11 | B659: Bent County | C659: 2020 | D659: 5477 | E659: 4071 | F659: 1406 | H659: 2136 | L659: 1.9058989
A660: 13 | B660: Boulder County | C660: 2020 | D660: 330923 | E660: 315633 | F660: 15290 | H660: 141291 | L660: 2.2339215
A661: 14 | B661: Broomfield County | C661: 2020 | D661: 74494 | E661: 74013 | F661: 481 | H661: 31463 | L661: 2.3523822
A662: 15 | B662: Chaffee County | C662: 2020 | D662: 19478 | E662: 18247 | F662: 1231 | H662: 10993 | L662: 1.6598745
A663: 17 | B663: Cheyenne County | C663: 2020 | D663: 1744 | E663: 1722 | F663: 22 | H663: 929 | L663: 1.853606
A664: 19 | B664: Clear Creek County | C664: 2020 | D664: 9397 | E664: 9315 | F664: 82 | H664: 5688 | L664: 1.6376582
... A847: 125 | B847: Yuma County | C847: 2022 | D847: 9920 | E847: 9757 | F847: 163 | H847: 4326 | L847: 2.2554323

Sheet JobsBySector
A1: county_fips | B1: county_name | C1: naics_code | D1: sector_name | E1: 2001 | F1: 2002 | G1: 2003 | H1: 2004 | I1: 2005 | J1: 2006 | K1: 2007 | L1: 2008 | M1: 2009 | N1: 2010 | O1: 2011 | P1: 2012 | Q1: 2013 | R1: 2014 | S1: 2015 | T1: 2016 | U1: 2017 | V1: 2018 | W1: 2019 | X1: 2020 | Y1: 2021 | Z1: 2022 | AA1: 2023 | AB1: 2024
A2: 1 | B2: Adams | C2: 1 | D2: Federal Government | E2: 2723 | F2: 2758 | G2: 2634 | H2: 2486 | I2: 2679 | J2: 2616 | K2: 2500 | L2: 1391 | M2: 1695 | N2: 1735 | O2: 1528 | P2: 1499 | Q2: 1339 | R2: 1344 | S2: 1347 | T2: 1360 | U2: 1111 | V2: 1786 | W2: 3083 | X2: 3203 | Y2: 3280 | Z2: 3370 | AA2: 3648 | AB2: 3599
A3: 1 | B3: Adams | C3: 10 | D3: Total All Sectors | E3: 164490 | F3: 163253 | G3: 160332 | H3: 163150 | I3: 170840 | J3: 176566 | K3: 179703 | L3: 179782 | M3: 175616 | N3: 174023 | O3: 181505 | P3: 186874 | Q3: 201504 | R3: 213091 | S3: 222880 | T3: 231243 | U3: 239873 | V3: 249861 | W3: 264853 | X3: 260951 | Y3: 270414 | Z3: 282653 | AA3: 291184 | AB3: 296280
A4: 1 | B4: Adams | C4: 11 | D4: Agriculture, Forestry, Fishing and Hunting | E4: 1421 | F4: 1332 | G4: 1224 | H4: 1078 | I4: 1234 | J4: 1122 | K4: 1112 | L4: 1272 | M4: 1224 | N4: 1075 | O4: 1068 | P4: 1144 | Q4: 1158 | R4: 1231 | S4: 1107 | T4: 1263 | U4: 1485 | V4: 1561 | W4: 1767 | X4: 1497 | Y4: 1361 | Z4: 1259 | AA4: 1058 | AB4: 1006
A5: 1 | B5: Adams | C5: 2 | D5: State Government | E5: 1805 | F5: 1832 | G5: 1792 | H5: 1759 | I5: 1799 | J5: 1727 | K5: 1718 | L5: 2027 | M5: 3310 | N5: 3457 | O5: 7795 | P5: 7875 | Q5: 14753 | R5: 15215 | S5: 15712 | T5: 16335 | U5: 17491 | V5: 18135 | W5: 20112 | X5: 20645 | Y5: 21409 | Z5: 22985 | AA5: 24177 | AB5: 25303
A6: 1 | B6: Adams | C6: 21 | D6: Mining, Quarrying, and Oil and Gas Extraction | E6: 313 | F6: 291 | G6: 254 | H6: 230 | I6: 352 | J6: 360 | K6: 357 | L6: 344 | M6: 356 | N6: 405 | O6: 501 | P6: 480 | Q6: 726 | R6: 878 | S6: 738 | T6: 714 | U6: 706 | V6: 716 | W6: 1444 | X6: 1012 | Y6: 1080 | Z6: 1106 | AA6: 1099 | AB6: 1122
A7: 1 | B7: Adams | C7: 22 | D7: Utilities | E7: 754 | F7: 754 | G7: 756 | H7: 769 | I7: 934 | J7: 643 | L7: 713 | M7: 674 | N7: 660 | O7: 614 | P7: 607 | Q7: 605 | R7: 673 | S7: 655 | T7: 641 | U7: 638 | V7: 633 | W7: 638 | X7: 636 | Y7: 652 | Z7: 696 | AA7: 801 | AB7: 791
A8: 1 | B8: Adams | C8: 23 | D8: Construction | E8: 23217 | F8: 22490 | G8: 20593 | H8: 20811 | I8: 21650 | J8: 22442 | K8: 21392 | L8: 20563 | M8: 18905 | N8: 17694 | O8: 17953 | P8: 18831 | Q8: 21625 | R8: 24433 | S8: 25415 | T8: 27550 | U8: 28091 | V8: 29518 | W8: 30360 | X8: 30755 | Y8: 30624 | Z8: 31466 | AA8: 33311 | AB8: 34133
A9: 1 | B9: Adams | C9: 3 | D9: Local Government | E9: 13520 | F9: 14558 | G9: 14937 | H9: 15351 | I9: 15789 | J9: 16344 | K9: 16556 | L9: 16817 | M9: 17077 | N9: 16947 | O9: 16735 | P9: 17098 | Q9: 17515 | R9: 17812 | S9: 18244 | T9: 18574 | U9: 18745 | V9: 19333 | W9: 20064 | X9: 19300 | Y9: 19610 | Z9: 20274 | AA9: 21811 | AB9: 22322
A10: 1 | B10: Adams | C10: 31-33 | D10: Manufacturing | E10: 15912 | F10: 15023 | G10: 13576 | H10: 13732 | I10: 14398 | J10: 14575 | K10: 13927 | L10: 12913 | M10: 11212 | N10: 11146 | O10: 11870 | P10: 12262 | Q10: 12477 | R10: 13658 | S10: 14252 | T10: 14143 | U10: 13990 | V10: 14340 | W10: 14937 | X10: 14733 | Y10: 15047 | Z10: 15297 | AA10: 14670 | AB10: 14035
A11: 1 | B11: Adams | C11: 42 | D11: Wholesale Trade | E11: 14033 | F11: 13687 | G11: 13314 | H11: 13571 | I11: 13992 | J11: 14750 | K11: 15298 | L11: 15178 | M11: 13811 | N11: 13604 | O11: 13823 | P11: 14053 | Q11: 14923 | R11: 15570 | S11: 16681 | T11: 16851 | U11: 17170 | V11: 17684 | W11: 17355 | X11: 17127 | Y11: 17330 | Z11: 18222 | AA11: 18602 | AB11: 18858
A12: 1 | B12: Adams | C12: 44-45 | D12: Retail Trade | E12: 18363 | F12: 17833 | G12: 17382 | H12: 17291 | I12: 18254 | J12: 18531 | K12: 19280 | L12: 19424 | M12: 18807 | N12: 18927 | O12: 19320 | P12: 20001 | Q12: 20533 | R12: 21658 | S12: 22638 | T12: 23061 | U12: 22960 | V12: 23271 | W12: 23649 | X12: 23242 | Y12: 24036 | Z12: 23526 | AA12: 24364 | AB12: 24880
A13: 1 | B13: Adams | C13: 48-49 | D13: Transportation and Warehousing | E13: 15025 | F13: 14961 | G13: 14669 | H13: 14711 | I13: 15084 | J13: 15027 | K13: 15302 | L13: 15292 | M13: 14545 | N13: 14165 | O13: 14470 | P13: 14622 | Q13: 15270 | R13: 16012 | S13: 17185 | T13: 18442 | U13: 20737 | V13: 24721 | W13: 28440 | X13: 33126 | Y13: 34033 | Z13: 35689 | AA13: 34912 | AB13: 35618
A14: 1 | B14: Adams | C14: 51 | D14: Information | E14: 2798 | F14: 2212 | G14: 2139 | H14: 2032 | I14: 2278 | J14: 2414 | K14: 2488 | L14: 2536 | M14: 2521 | N14: 2302 | O14: 2810 | P14: 2675 | Q14: 2800 | R14: 2863 | S14: 2903 | T14: 3059 | U14: 3164 | V14: 2913 | W14: 2938 | X14: 2552 | Y14: 2815 | Z14: 2939 | AA14: 2895 | AB14: 2802
A15: 1 | B15: Adams | C15: 52 | D15: Finance and Insurance | E15: 3551 | F15: 3694 | G15: 4042 | H15: 4061 | I15: 3718 | J15: 3887 | K15: 3823 | L15: 3657 | M15: 3551 | N15: 3351 | O15: 3418 | P15: 3525 | Q15: 3651 | R15: 3772 | S15: 3848 | T15: 3921 | U15: 4195 | V15: 4235 | W15: 4134 | X15: 4082 | Y15: 4146 | Z15: 4290 | AA15: 4553 | AB15: 4073
A16: 1 | B16: Adams | C16: 53 | D16: Real Estate and Rental and Leasing | E16: 4290 | F16: 4349 | G16: 4676 | H16: 4940 | I16: 5240 | J16: 5137 | K16: 5142 | L16: 4935 | M16: 4943 | N16: 4761 | O16: 4772 | P16: 4939 | Q16: 5186 | R16: 5300 | S16: 5697 | T16: 5965 | U16: 6097 | V16: 6325 | W16: 6463 | X16: 6283 | Y16: 6652 | Z16: 6776 | AA16: 6779 | AB16: 7087
A17: 1 | B17: Adams | C17: 54 | D17: Professional, Scientific, and Technical Services | E17: 5897 | F17: 5768 | G17: 6053 | H17: 6097 | I17: 6681 | J17: 6870 | K17: 7271 | L17: 7818 | M17: 7985 | N17: 8167 | O17: 8347 | P17: 8722 | Q17: 8481 | R17: 8988 | S17: 9785 | T17: 10160 | U17: 10798 | V17: 11056 | W17: 11462 | X17: 11530 | Y17: 12539 | Z17: 13551 | AA17: 14019 | AB17: 14744
A18: 1 | B18: Adams | C18: 55 | D18: Management of Companies and Enterprises | E18: 954 | F18: 974 | G18: 1032 | H18: 1177 | I18: 1395 | J18: 1568 | K18: 1353 | L18: 1263 | M18: 1576 | N18: 1639 | O18: 1275 | P18: 1243 | Q18: 1318 | R18: 1370 | S18: 1476 | T18: 1686 | U18: 1738 | V18: 1732 | W18: 1710 | X18: 1787 | Y18: 1957 | Z18: 1731 | AA18: 1718 | AB18: 1847
A19: 1 | B19: Adams | C19: 56 | D19: Administrative and Support and Waste Management and Remediation Services | E19: 9994 | F19: 10349 | G19: 10450 | H19: 10715 | I19: 11208 | J19: 12631 | K19: 13492 | L19: 12727 | M19: 11986 | N19: 12261 | O19: 12868 | P19: 13552 | Q19: 13343 | R19: 14251 | S19: 15420 | T19: 16011 | U19: 17190 | V19: 17666 | W19: 18996 | X19: 18401 | Y19: 19329 | Z19: 20965 | AA19: 21502 | AB19: 21406
A20: 1 | B20: Adams | C20: 61 | D20: Educational Services | E20: 921 | F20: 1043 | G20: 1332 | H20: 1590 | I20: 1942 | J20: 2118 | K20: 2207 | L20: 2190 | M20: 2405 | N20: 2345 | O20: 2029 | P20: 1990 | Q20: 1785 | R20: 2157 | S20: 1959 | T20: 1776 | U20: 1835 | V20: 1877 | W20: 1980 | X20: 1741 | Y20: 1896 | Z20: 2128 | AA20: 2187 | AB20: 2256
A21: 1 | B21: Adams | C21: 62 | D21: Health Care and Social Assistance | E21: 9847 | F21: 9929 | G21: 10280 | H21: 10525 | I21: 11123 | J21: 11863 | K21: 13121 | L21: 15418 | M21: 16057 | N21: 16615 | O21: 16828 | P21: 17731 | Q21: 18515 | R21: 19035 | S21: 19785 | T21: 20631 | U21: 21292 | V21: 21896 | W21: 22674 | X21: 20442 | Y21: 21092 | Z21: 21827 | AA21: 23291 | AB21: 24443
A22: 1 | B22: Adams | C22: 71 | D22: Arts, Entertainment, and Recreation | E22: 1487 | F22: 1589 | G22: 1561 | H22: 1653 | I22: 1824 | J22: 1883 | K22: 2084 | L22: 2057 | M22: 2003 | N22: 2077 | O22: 2099 | P22: 2274 | Q22: 2591 | R22: 2675 | S22: 2721 | T22: 2938 | U22: 3238 | V22: 3444 | W22: 4073 | X22: 3236 | Y22: 3676 | Z22: 4075 | AA22: 4642 | AB22: 4787
A23: 1 | B23: Adams | C23: 72 | D23: Accommodation and Food Services | E23: 10624 | F23: 10734 | G23: 10373 | H23: 10765 | I23: 11190 | J23: 11793 | K23: 12221 | L23: 12841 | M23: 12598 | N23: 12310 | O23: 12581 | P23: 12862 | Q23: 13747 | R23: 14542 | S23: 15249 | T23: 16013 | U23: 16746 | V23: 17264 | W23: 18717 | X23: 16318 | Y23: 17802 | Z23: 19666 | AA23: 19860 | AB23: 19651
A24: 1 | B24: Adams | C24: 81 | D24: Other Services (except Public Administration) | E24: 6926 | F24: 6986 | G24: 7150 | H24: 7665 | I24: 8060 | J24: 8239 | K24: 8357 | L24: 8379 | M24: 8353 | N24: 8361 | O24: 8788 | P24: 8865 | Q24: 9136 | R24: 9604 | S24: 10025 | T24: 10112 | U24: 10430 | V24: 9730 | W24: 9829 | X24: 9278 | Y24: 9993 | Z24: 10763 | AA24: 11226 | AB24: 11480
A25: 1 | B25: Adams | C25: 99 | D25: Unclassified | E25: 1 | F25: 0 | G25: 3 | H25: 1 | I25: 10 | J25: 16 | L25: 18 | M25: 8 | N25: 9 | O25: 2 | P25: 11 | Q25: 16 | R25: 37 | S25: 28 | T25: 26 | U25: 16 | V25: 13 | W25: 16 | X25: 15 | Y25: 47 | Z25: 43 | AA25: 51 | AB25: 27
A26: 3 | B26: Alamosa | C26: 1 | D26: Federal Government | E26: 157 | F26: 166 | G26: 167 | H26: 161 | I26: 162 | J26: 165 | K26: 163 | L26: 167 | M26: 171 | N26: 181 | O26: 173 | P26: 168 | Q26: 154 | R26: 140 | S26: 144 | T26: 142 | U26: 139 | V26: 134 | W26: 132 | X26: 139 | Y26: 137 | Z26: 129 | AA26: 129 | AB26: 131
A27: 3 | B27: Alamosa | C27: 10 | D27: Total All Sectors | E27: 8398 | F27: 8492 | G27: 8653 | H27: 8663 | I27: 8697 | J27: 8756 | K27: 8805 | L27: 8868 | M27: 8800 | N27: 8911 | O27: 8845 | P27: 8617 | Q27: 8551 | R27: 8584 | S27: 8905 | T27: 9169 | U27: 9349 | V27: 9430 | W27: 9544 | X27: 9137 | Y27: 9376 | Z27: 9630 | AA27: 9461 | AB27: 9394
A28: 3 | B28: Alamosa | C28: 11 | D28: Agriculture, Forestry, Fishing and Hunting | E28: 447 | F28: 439 | G28: 454 | H28: 482 | I28: 484 | J28: 494 | K28: 463 | L28: 468 | M28: 475 | N28: 490 | O28: 501 | P28: 352 | Q28: 286 | R28: 270 | S28: 369 | T28: 417 | U28: 457 | V28: 508 | W28: 475 | X28: 421 | Y28: 406 | Z28: 344 | AA28: 278 | AB28: 313
A29: 3 | B29: Alamosa | C29: 2 | D29: State Government | E29: 687 | F29: 697 | G29: 723 | H29: 753 | I29: 814 | J29: 809 | K29: 815 | L29: 847 | M29: 815 | N29: 838 | O29: 853 | P29: 861 | Q29: 878 | R29: 869 | S29: 859 | T29: 844 | U29: 884 | V29: 874 | W29: 849 | X29: 830 | Y29: 821 | Z29: 825 | AA29: 845 | AB29: 857
A30: 3 | B30: Alamosa | C30: 21 | D30: Mining, Quarrying, and Oil and Gas Extraction | E30: 88 | F30: 62 | G30: 66 | H30: 67 | I30: 65 | J30: 56 | V30: 33 | W30: 35 | Z30: 14 | AA30: 14
A31: 3 | B31: Alamosa | C31: 22 | D31: Utilities | M31: 59 | N31: 57 | O31: 78 | P31: 77 | Q31: 73 | R31: 82 | S31: 95 | T31: 86 | U31: 55 | Y31: 61 | Z31: 68 | AA31: 73 | AB31: 83
A32: 3 | B32: Alamosa | C32: 23 | D32: Construction | E32: 584 | F32: 587 | G32: 622 | H32: 557 | I32: 547 | J32: 512 | K32: 590 | L32: 618 | M32: 509 | N32: 558 | O32: 509 | P32: 469 | Q32: 470 | R32: 423 | S32: 447 | T32: 495 | U32: 496 | V32: 536 | W32: 540 | X32: 537 | Y32: 507 | Z32: 500 | AA32: 552 | AB32: 610
A33: 3 | B33: Alamosa | C33: 3 | D33: Local Government | E33: 993 | F33: 977 | G33: 1002 | H33: 1021 | I33: 1007 | J33: 992 | K33: 973 | L33: 981 | M33: 974 | N33: 973 | O33: 950 | P33: 944 | Q33: 945 | R33: 962 | S33: 973 | T33: 991 | U33: 1011 | V33: 1010 | W33: 988 | X33: 928 | Y33: 910 | Z33: 941 | AA33: 992 | AB33: 974
A34: 3 | B34: Alamosa | C34: 31-33 | D34: Manufacturing | E34: 118 | F34: 119 | G34: 119 | H34: 140 | I34: 141 | J34: 147 | K34: 135 | L34: 124 | M34: 137 | N34: 119 | O34: 147 | P34: 151 | Q34: 148 | R34: 152 | S34: 147 | T34: 133 | U34: 138 | V34: 139 | W34: 142 | X34: 144 | Y34: 172 | Z34: 166 | AA34: 153 | AB34: 142
A35: 3 | B35: Alamosa | C35: 42 | D35: Wholesale Trade | E35: 230 | F35: 221 | G35: 219 | H35: 219 | I35: 222 | J35: 224 | K35: 223 | L35: 224 | M35: 192 | N35: 204 | O35: 193 | P35: 199 | Q35: 201 | R35: 190 | S35: 215 | T35: 202 | U35: 193 | V35: 182 | W35: 180 | X35: 167 | Y35: 169 | Z35: 167 | AA35: 158 | AB35: 167
A36: 3 | B36: Alamosa | C36: 44-45 | D36: Retail Trade | E36: 1348 | F36: 1332 | G36: 1233 | H36: 1206 | I36: 1221 | J36: 1186 | K36: 1219 | L36: 1214 | M36: 1233 | N36: 1216 | O36: 1200 | P36: 1174 | Q36: 1149 | R36: 1166 | S36: 1187 | T36: 1241 | U36: 1242 | V36: 1240 | W36: 1188 | X36: 1165 | Y36: 1141 | Z36: 1135 | AA36: 1175 | AB36: 1182
A37: 3 | B37: Alamosa | C37: 48-49 | D37: Transportation and Warehousing | E37: 183 | F37: 182 | G37: 186 | H37: 184 | I37: 187 | J37: 198 | K37: 197 | L37: 214 | M37: 197 | N37: 200 | O37: 232 | P37: 239 | Q37: 230 | R37: 254 | S37: 261 | T37: 245 | U37: 248 | V37: 237 | W37: 251 | X37: 283 | Y37: 306 | Z37: 301 | AA37: 266 | AB37: 234
A38: 3 | B38: Alamosa | C38: 51 | D38: Information | E38: 131 | F38: 129 | G38: 120 | H38: 133 | I38: 135 | J38: 141 | K38: 131 | L38: 118 | M38: 120 | N38: 111 | O38: 104 | P38: 101 | Q38: 95 | R38: 95 | S38: 95 | T38: 96 | U38: 99 | V38: 91 | W38: 85 | X38: 67 | Y38: 73 | Z38: 76 | AA38: 65 | AB38: 54
A39: 3 | B39: Alamosa | C39: 52 | D39: Finance and Insurance | E39: 251 | F39: 261 | G39: 260 | H39: 277 | I39: 316 | J39: 326 | K39: 329 | L39: 322 | M39: 317 | N39: 309 | O39: 289 | P39: 297 | Q39: 319 | R39: 326 | S39: 337 | T39: 339 | U39: 338 | V39: 339 | W39: 339 | X39: 375 | Y39: 465 | Z39: 761 | AA39: 489 | AB39: 289
A40: 3 | B40: Alamosa | C40: 53 | D40: Real Estate and Rental and Leasing | E40: 205 | F40: 220 | G40: 231 | H40: 236 | I40: 241 | J40: 221 | K40: 212 | L40: 172 | M40: 222 | N40: 239 | O40: 227 | P40: 229 | Q40: 241 | R40: 226 | S40: 231 | T40: 239 | U40: 238 | V40: 238 | W40: 247 | X40: 243 | Y40: 266 | Z40: 253 | AA40: 253 | AB40: 243
...

Sheet Lookups
A1: {=_xlfn.UNIQUE(CountyHousingProf!B2:B197)} -> name | B1: =CountyHousingProf!A2 -> countyfips | C1: area (sq. mi) | D1: region
A2: COLORADO STATE | B2: =_xlfn.XLOOKUP(A2,CountyHousingProf!$B$3:$B$197,CountyHousingProf!$A$3:$A$197) -> 000 | C2: =SUM(C3:C66) -> 104095.97
A3: ADAMS COUNTY | B3: =_xlfn.XLOOKUP(A3,CountyHousingProf!$B$3:$B$197,CountyHousingProf!$A$3:$A$197) -> 001 | C3: 1182.29 | D3: 3
A4: ALAMOSA COUNTY | B4: =_xlfn.XLOOKUP(A4,CountyHousingProf!$B$3:$B$197,CountyHousingProf!$A$3:$A$197) -> 003 | C4: 723.21 | D4: 8
A5: ARAPAHOE COUNTY | B5: =_xlfn.XLOOKUP(A5,CountyHousingProf!$B$3:$B$197,CountyHousingProf!$A$3:$A$197) -> 005 | C5: 804.41 | D5: 3
A6: ARCHULETA COUNTY | B6: =_xlfn.XLOOKUP(A6,CountyHousingProf!$B$3:$B$197,CountyHousingProf!$A$3:$A$197) -> 007 | C6: 1354.53 | D6: 9
A7: BACA COUNTY | B7: =_xlfn.XLOOKUP(A7,CountyHousingProf!$B$3:$B$197,CountyHousingProf!$A$3:$A$197) -> 009 | C7: 2558.48 | D7: 6
A8: BENT COUNTY | B8: =_xlfn.XLOOKUP(A8,CountyHousingProf!$B$3:$B$197,CountyHousingProf!$A$3:$A$197) -> 011 | C8: 1541.07 | D8: 6
A9: BOULDER COUNTY | B9: =_xlfn.XLOOKUP(A9,CountyHousingProf!$B$3:$B$197,CountyHousingProf!$A$3:$A$197) -> 013 | C9: 740.48 | D9: 3
A10: BROOMFIELD COUNTY | B10: =_xlfn.XLOOKUP(A10,CountyHousingProf!$B$3:$B$197,CountyHousingProf!$A$3:$A$197) -> 014 | C10: 33.57 | D10: 3
A11: CHAFFEE COUNTY | B11: =_xlfn.XLOOKUP(A11,CountyHousingProf!$B$3:$B$197,CountyHousingProf!$A$3:$A$197) -> 015 | C11: 1014.12 | D11: 13
A12: CHEYENNE COUNTY | B12: =_xlfn.XLOOKUP(A12,CountyHousingProf!$B$3:$B$197,CountyHousingProf!$A$3:$A$197) -> 017 | C12: 1781.9 | D12: 5
A13: CLEAR CREEK COUNTY | B13: =_xlfn.XLOOKUP(A13,CountyHousingProf!$B$3:$B$197,CountyHousingProf!$A$3:$A$197) -> 019 | C13: 396.53 | D13: 3
A14: CONEJOS COUNTY | B14: =_xlfn.XLOOKUP(A14,CountyHousingProf!$B$3:$B$197,CountyHousingProf!$A$3:$A$197) -> 021 | C14: 1290.22 | D14: 8
... A66: YUMA COUNTY | B66: =_xlfn.XLOOKUP(A66,CountyHousingProf!$B$3:$B$197,CountyHousingProf!$A$3:$A$197) -> 125 | C66: 2369.61 | D66: 1

Sheet COMB_RAW_DATA
A1: County FIPS | B1: Region | C1: County | D1: Year | E1: Total Population | F1: Household Population | G1: Group Quarters Population | H1: Household Size | I1: Total Housing Units | J1: Occupied Housing Units | K1: Vacant Housing Units | L1: Vacancy Percent | M1: Household Population to Total Housing Units Ratio | N1: Density (pers/sq mi) | O1: totalpopulation | P1: births | Q1: naturalincrease | R1: netmigration | S1: deaths | T1: totalhousingunits | U1: households | V1: householdsize | W1: householdpopulation | X1: censusbuildingpermits | Y1: vacancyrate | Z1: vacanthousingunits | AA1: hhldpoptothuratio
A2: 1 | B2: 3 | C2: Adams County | D2: 2010 | E2: 443711 | F2: 439684 | G2: 4027 | H2: 2.85 | I2: 163435 | J2: 154505 | K2: 8930 | L2: 5.46 | M2: 2.6902683 | N2: =E2/_xlfn.XLOOKUP(C2,Lookups!$A$2:$A$66,Lookups!$C$2:$C$66) -> 375.29794
A3: 1 | B3: 3 | C3: Adams County | D3: 2011 | E3: 452181 | F3: 448120 | G3: 4061 | H3: 2.85 | I3: 164593 | J3: 157248 | K3: 7345 | L3: 4.46 | M3: 2.7225945 | N3: =E3/_xlfn.XLOOKUP(C3,Lookups!$A$2:$A$66,Lookups!$C$2:$C$66) -> 382.462
A4: 1 | B4: 3 | C4: Adams County | D4: 2012 | E4: 460468 | F4: 456411 | G4: 4057 | H4: 2.85 | I4: 165858 | J4: 159932 | K4: 5926 | L4: 3.57 | M4: 2.7518178 | N4: =E4/_xlfn.XLOOKUP(C4,Lookups!$A$2:$A$66,Lookups!$C$2:$C$66) -> 389.47128
A5: 1 | B5: 3 | C5: Adams County | D5: 2013 | E5: 469878 | F5: 465792 | G5: 4086 | H5: 2.86 | I5: 167459 | J5: 162991 | K5: 4468 | L5: 2.67 | M5: 2.7815286 | N5: =E5/_xlfn.XLOOKUP(C5,Lookups!$A$2:$A$66,Lookups!$C$2:$C$66) -> 397.43041
A6: 1 | B6: 3 | C6: Adams County | D6: 2014 | E6: 479901 | F6: 475690 | G6: 4211 | H6: 2.86 | I6: 169377 | J6: 166221 | K6: 3156 | L6: 1.86 | M6: 2.8084687 | N6: =E6/_xlfn.XLOOKUP(C6,Lookups!$A$2:$A$66,Lookups!$C$2:$C$66) -> 405.90803
A7: 1 | B7: 3 | C7: Adams County | D7: 2015 | E7: 490351 | F7: 486126 | G7: 4225 | H7: 2.87 | I7: 171361 | J7: 169630 | K7: 1731 | L7: 1.01 | M7: 2.8368532 | N7: =E7/_xlfn.XLOOKUP(C7,Lookups!$A$2:$A$66,Lookups!$C$2:$C$66) -> 414.7468
A8: 1 | B8: 3 | C8: Adams County | D8: 2016 | E8: 497822 | F8: 493406 | G8: 4416 | H8: 2.87 | I8: 173204 | J8: 171930 | K8: 1274 | L8: 0.74 | M8: 2.8486986 | N8: =E8/_xlfn.XLOOKUP(C8,Lookups!$A$2:$A$66,Lookups!$C$2:$C$66) -> 421.0659
A9: 1 | B9: 3 | C9: Adams County | D9: 2017 | E9: 503706 | F9: 499300 | G9: 4406 | H9: 2.87 | I9: 176439 | J9: 173741 | K9: 2698 | L9: 1.53 | M9: 2.8298732 | N9: =E9/_xlfn.XLOOKUP(C9,Lookups!$A$2:$A$66,Lookups!$C$2:$C$66) -> 426.04268
A10: 1 | B10: 3 | C10: Adams County | D10: 2018 | E10: 511422 | F10: 506996 | G10: 4426 | H10: 2.88 | I10: 180056 | J10: 176173 | K10: 3883 | L10: 2.16 | M10: 2.8157684 | N10: =E10/_xlfn.XLOOKUP(C10,Lookups!$A$2:$A$66,Lookups!$C$2:$C$66) -> 432.569
A11: 1 | B11: 3 | C11: Adams County | D11: 2019 | E11: 516482 | F11: 512038 | G11: 4444 | H11: 2.88 | I11: 183751 | J11: 177677 | K11: 6074 | L11: 3.31 | M11: 2.7865862 | N11: =E11/_xlfn.XLOOKUP(C11,Lookups!$A$2:$A$66,Lookups!$C$2:$C$66) -> 436.84883
A12: 1 | B12: 3 | C12: Adams County | D12: 2020 | E12: 520433 | F12: 515957 | G12: 4476 | I12: 187288 | M12: 2.7548855 | N12: =E12/_xlfn.XLOOKUP(C12,Lookups!$A$2:$A$66,Lookups!$C$2:$C$66) -> 440.19065 | O12: 520433 | P12: 6805 | Q12: 3403 | R12: 548 | S12: 3402 | T12: 187288 | W12: 515957 | X12: 4027 | AA12: 2.7548855
A13: 1 | B13: 3 | C13: Adams County | D13: 2021 | E13: 523417 | F13: 518896 | G13: 4521 | I13: 191198 | M13: 2.7139196 | N13: =E13/_xlfn.XLOOKUP(C13,Lookups!$A$2:$A$66,Lookups!$C$2:$C$66) -> 442.71456 | O13: 523417 | P13: 6644 | Q13: 2686 | R13: 298 | S13: 3958 | T13: 191198 | W13: 518896 | X13: 4687 | AA13: 2.7139196
A14: 1 | B14: 3 | C14: Adams County | D14: 2022 | E14: 527501 | F14: 522937 | G14: 4564 | I14: 196741 | M14: 2.6579971 | N14: =E14/_xlfn.XLOOKUP(C14,Lookups!$A$2:$A$66,Lookups!$C$2:$C$66) -> 446.16888 | O14: 527501 | P14: 6838 | Q14: 2544 | R14: 1540 | S14: 4294 | T14: 196741 | W14: 522937 | X14: 2811 | AA14: 2.6579971
A15: 3 | B15: 8 | C15: Alamosa County | D15: 2010 | E15: 15474 | F15: 14734 | G15: 740 | H15: 2.45 | I15: 6561 | J15: 6007 | K15: 554 | L15: 8.44 | M15: 2.2456943 | N15: =E15/_xlfn.XLOOKUP(C15,Lookups!$A$2:$A$66,Lookups!$C$2:$C$66) -> 21.396275
A16: 3 | B16: 8 | C16: Alamosa County | D16: 2011 | E16: 15528 | F16: 14788 | G16: 740 | H16: 2.45 | I16: 6591 | J16: 6037 | K16: 554 | L16: 8.41 | M16: 2.2436656 | N16: =E16/_xlfn.XLOOKUP(C16,Lookups!$A$2:$A$66,Lookups!$C$2:$C$66) -> 21.470942
A17: 3 | B17: 8 | C17: Alamosa County | D17: 2012 | E17: 15604 | F17: 14864 | G17: 740 | H17: 2.45 | I17: 6636 | J17: 6075 | K17: 561 | L17: 8.45 | M17: 2.2399036 | N17: =E17/_xlfn.XLOOKUP(C17,Lookups!$A$2:$A$66,Lookups!$C$2:$C$66) -> 21.576029
A18: 3 | B18: 8 | C18: Alamosa County | D18: 2013 | E18: 15709 | F18: 14969 | G18: 740 | H18: 2.44 | I18: 6700 | J18: 6126 | K18: 574 | L18: 8.57 | M18: 2.2341791 | N18: =E18/_xlfn.XLOOKUP(C18,Lookups!$A$2:$A$66,Lookups!$C$2:$C$66) -> 21.721215
A19: 3 | B19: 8 | C19: Alamosa County | D19: 2014 | E19: 15788 | F19: 14923 | G19: 865 | H19: 2.44 | I19: 6747 | J19: 6115 | K19: 632 | L19: 9.37 | M19: 2.2117978 | N19: =E19/_xlfn.XLOOKUP(C19,Lookups!$A$2:$A$66,Lookups!$C$2:$C$66) -> 21.83045
A20: 3 | B20: 8 | C20: Alamosa County | D20: 2015 | E20: 15885 | F20: 15020 | G20: 865 | H20: 2.44 | I20: 6807 | J20: 6163 | K20: 644 | L20: 9.46 | M20: 2.2065521 | N20: =E20/_xlfn.XLOOKUP(C20,Lookups!$A$2:$A$66,Lookups!$C$2:$C$66) -> 21.964575
A21: 3 | B21: 8 | C21: Alamosa County | D21: 2016 | E21: 15936 | F21: 15071 | G21: 865 | H21: 2.43 | I21: 6835 | J21: 6192 | K21: 643 | L21: 9.41 | M21: 2.2049744 | N21: =E21/_xlfn.XLOOKUP(C21,Lookups!$A$2:$A$66,Lookups!$C$2:$C$66) -> 22.035094
A22: 3 | B22: 8 | C22: Alamosa County | D22: 2017 | E22: 16053 | F22: 15188 | G22: 865 | H22: 2.43 | I22: 6908 | J22: 6247 | K22: 661 | L22: 9.57 | M22: 2.1986103 | N22: =E22/_xlfn.XLOOKUP(C22,Lookups!$A$2:$A$66,Lookups!$C$2:$C$66) -> 22.196872
A23: 3 | B23: 8 | C23: Alamosa County | D23: 2018 | E23: 16184 | F23: 15319 | G23: 865 | H23: 2.43 | I23: 6990 | J23: 6310 | K23: 680 | L23: 9.73 | M23: 2.1915594 | N23: =E23/_xlfn.XLOOKUP(C23,Lookups!$A$2:$A$66,Lookups!$C$2:$C$66) -> 22.378009
A24: 3 | B24: 8 | C24: Alamosa County | D24: 2019 | E24: 16247 | F24: 15382 | G24: 865 | H24: 2.43 | I24: 7026 | J24: 6343 | K24: 683 | L24: 9.72 | M24: 2.1892969 | N24: =E24/_xlfn.XLOOKUP(C24,Lookups!$A$2:$A$66,Lookups!$C$2:$C$66) -> 22.465121
A25: 3 | B25: 8 | C25: Alamosa County | D25: 2020 | E25: 16371 | F25: 15411 | G25: 960 | I25: 7072 | M25: 2.1791572 | N25: =E25/_xlfn.XLOOKUP(C25,Lookups!$A$2:$A$66,Lookups!$C$2:$C$66) -> 22.636579 | O25: 16371 | P25: 187 | Q25: 28 | R25: 96 | S25: 159 | T25: 7072 | W25: 15411 | X25: 62 | AA25: 2.1791572
A26: 3 | B26: 8 | C26: Alamosa County | D26: 2021 | E26: 16574 | F26: 15590 | G26: 984 | I26: 7137 | M26: 2.1843912 | N26: =E26/_xlfn.XLOOKUP(C26,Lookups!$A$2:$A$66,Lookups!$C$2:$C$66) -> 22.917272 | O26: 16574 | P26: 188 | Q26: 26 | R26: 177 | S26: 162 | T26: 7137 | W26: 15590 | X26: 109 | AA26: 2.1843912
A27: 3 | B27: 8 | C27: Alamosa County | D27: 2022 | E27: 16575 | F27: 15609 | G27: 966 | I27: 7250 | M27: 2.1529655 | N27: =E27/_xlfn.XLOOKUP(C27,Lookups!$A$2:$A$66,Lookups!$C$2:$C$66) -> 22.918654 | O27: 16575 | P27: 196 | Q27: -11 | R27: 12 | S27: 207 | T27: 7250 | W27: 15609 | X27: 102 | AA27: 2.1529655
A28: 5 | B28: 3 | C28: Arapahoe County | D28: 2010 | E28: 574819 | F28: 569899 | G28: 4920 | H28: 2.53 | I28: 239171 | J28: 225108 | K28: 14063 | L28: 5.88 | M28: 2.3828098 | N28: =E28/_xlfn.XLOOKUP(C28,Lookups!$A$2:$A$66,Lookups!$C$2:$C$66) -> 714.5846
A29: 5 | B29: 3 | C29: Arapahoe County | D29: 2011 | E29: 585817 | F29: 580907 | G29: 4910 | H29: 2.54 | I29: 240616 | J29: 228868 | K29: 11748 | L29: 4.88 | M29: 2.4142493 | N29: =E29/_xlfn.XLOOKUP(C29,Lookups!$A$2:$A$66,Lookups!$C$2:$C$66) -> 728.25673
A30: 5 | B30: 3 | C30: Arapahoe County | D30: 2012 | E30: 596228 | F30: 591240 | G30: 4988 | H30: 2.54 | I30: 241137 | J30: 232344 | K30: 8793 | L30: 3.65 | M30: 2.4518842 | N30: =E30/_xlfn.XLOOKUP(C30,Lookups!$A$2:$A$66,Lookups!$C$2:$C$66) -> 741.19914
A31: 5 | B31: 3 | C31: Arapahoe County | D31: 2013 | E31: 607861 | F31: 602977 | G31: 4884 | H31: 2.55 | I31: 242604 | J31: 236352 | K31: 6252 | L31: 2.58 | M31: 2.4854372 | N31: =E31/_xlfn.XLOOKUP(C31,Lookups!$A$2:$A$66,Lookups!$C$2:$C$66) -> 755.66067
A32: 5 | B32: 3 | C32: Arapahoe County | D32: 2014 | E32: 618310 | F32: 613335 | G32: 4975 | H32: 2.56 | I32: 245659 | J32: 239801 | K32: 5858 | L32: 2.38 | M32: 2.4966926 | N32: =E32/_xlfn.XLOOKUP(C32,Lookups!$A$2:$A$66,Lookups!$C$2:$C$66) -> 768.65032
A33: 5 | B33: 3 | C33: Arapahoe County | D33: 2015 | E33: 629965 | F33: 625080 | G33: 4885 | H33: 2.56 | I33: 247801 | J33: 243773 | K33: 4028 | L33: 1.63 | M33: 2.522508 | N33: =E33/_xlfn.XLOOKUP(C33,Lookups!$A$2:$A$66,Lookups!$C$2:$C$66) -> 783.1392
A34: 5 | B34: 3 | C34: Arapahoe County | D34: 2016 | E34: 637656 | F34: 632707 | G34: 4949 | H34: 2.57 | I34: 249881 | J34: 246123 | K34: 3758 | L34: 1.5 | M34: 2.5320332 | N34: =E34/_xlfn.XLOOKUP(C34,Lookups!$A$2:$A$66,Lookups!$C$2:$C$66) -> 792.70024
A35: 5 | B35: 3 | C35: Arapahoe County | D35: 2017 | E35: 642976 | F35: 637915 | G35: 5061 | H35: 2.58 | I35: 254352 | J35: 247523 | K35: 6829 | L35: 2.68 | M35: 2.5080007 | N35: =E35/_xlfn.XLOOKUP(C35,Lookups!$A$2:$A$66,Lookups!$C$2:$C$66) -> 799.31378
A36: 5 | B36: 3 | C36: Arapahoe County | D36: 2018 | E36: 650167 | F36: 644993 | G36: 5174 | H36: 2.58 | I36: 257003 | J36: 249640 | K36: 7363 | L36: 2.86 | M36: 2.5096711 | N36: =E36/_xlfn.XLOOKUP(C36,Lookups!$A$2:$A$66,Lookups!$C$2:$C$66) -> 808.25325
A37: 5 | B37: 3 | C37: Arapahoe County | D37: 2019 | E37: 653804 | F37: 648519 | G37: 5285 | H37: 2.59 | I37: 259939 | J37: 250374 | K37: 9565 | L37: 3.68 | M37: 2.4948892 | N37: =E37/_xlfn.XLOOKUP(C37,Lookups!$A$2:$A$66,Lookups!$C$2:$C$66) -> 812.77458
A38: 5 | B38: 3 | C38: Arapahoe County | D38: 2020 | E38: 655212 | F38: 649825 | G38: 5387 | I38: 263241 | M38: 2.4685554 | N38: =E38/_xlfn.XLOOKUP(C38,Lookups!$A$2:$A$66,Lookups!$C$2:$C$66) -> 814.52493 | O38: 655212 | P38: 7580 | Q38: 2964 | R38: -1556 | S38: 4616 | T38: 263241 | W38: 649825 | X38: 4116 | AA38: 2.4685554
A39: 5 | B39: 3 | C39: Arapahoe County | D39: 2021 | E39: 656722 | F39: 651475 | G39: 5247 | I39: 266515 | M39: 2.4444215 | N39: =E39/_xlfn.XLOOKUP(C39,Lookups!$A$2:$A$66,Lookups!$C$2:$C$66) -> 816.40208 | O39: 656722 | P39: 7551 | Q39: 2814 | R39: -1304 | S39: 4737 | T39: 266515 | W39: 651475 | X39: 5519 | AA39: 2.4444215
A40: 5 | B40: 3 | C40: Arapahoe County | D40: 2022 | E40: 656015 | F40: 650714 | G40: 5301 | I40: 270939 | M40: 2.4016993 | N40: =E40/_xlfn.XLOOKUP(C40,Lookups!$A$2:$A$66,Lookups!$C$2:$C$66) -> 815.52318 | O40: 656015 | P40: 7612 | Q40: 2532 | R40: -3239 | S40: 5080 | T40: 270939 | W40: 650714 | X40: 4325 | AA40: 2.4016993
...

Sheet COUNTY_PIVOT
B3: Column Labels | AG3: Change in Population Density (% change year-on-year, 2010 baseline) | AW3: Change in Population Density (3-year rolling avg, 2010 baseline)
A4: Row Labels | B4: 2010 | C4: 2011 | D4: 2012 | E4: 2013 | F4: 2014 | G4: 2015 | H4: 2016 | I4: 2017 | J4: 2018 | K4: 2019 | L4: 2020 | M4: 2021 | N4: 2022 | O4: Grand Total | AD4: 2021 | AE4: 2022 | AG4: Row Labels | AH4: 2010 | AI4: 2011 | AJ4: 2012 | AK4: 2013 | AL4: 2014 | AM4: 2015 | AN4: 2016 | AO4: 2017 | AP4: 2018 | AQ4: 2019 | AR4: 2020 | AS4: 2021 | AT4: 2022 | AW4: Row Labels | AX4: CY 10-12 | AY4: CY 11-13 | AZ4: CY 12-14 | BA4: CY 13-15 | BB4: CY 14-16 | BC4: CY 15-17 | BD4: CY 16-18 | BE4: CY 17-19 | BF4: CY 18-20 | BG4: CY 19-21 | BH4: CY 20-22
A5: Adams County | AD5: 442.71456 | AE5: 446.16888 | AG5: Adams County | AH5: =0 -> 0 | AI5: =(T5-S5)/T5 -> #DIV/0! | AJ5: =(U5-T5)/U5 -> #DIV/0! | AK5: =(V5-U5)/V5 -> #DIV/0! | AL5: =(W5-V5)/W5 -> #DIV/0! | AM5: =(X5-W5)/X5 -> #DIV/0! | AN5: =(Y5-X5)/Y5 -> #DIV/0! | AO5: =(Z5-Y5)/Z5 -> #DIV/0! | AP5: =(AA5-Z5)/AA5 -> #DIV/0! | ... AT5: =(AE5-AD5)/AE5 -> 0.0077421654 | AW5: Adams County | AX5: =AVERAGE(AH5:AJ5) -> #DIV/0! | AY5: =AVERAGE(AI5:AK5) -> #DIV/0! | AZ5: =AVERAGE(AJ5:AL5) -> #DIV/0! | BA5: =AVERAGE(AK5:AM5) -> #DIV/0! | BB5: =AVERAGE(AL5:AN5) -> #DIV/0! | BC5: =AVERAGE(AM5:AO5) -> #DIV/0! | BD5: =AVERAGE(AN5:AP5) -> #DIV/0! | BE5: =AVERAGE(AO5:AQ5) -> #DIV/0! | ... BH5: =AVERAGE(AR5:AT5) -> #DIV/0!
A6: Alamosa County | AD6: 22.917272 | AE6: 22.918654 | AG6: Alamosa County | AH6: =0 -> 0 | AI6: =(T6-S6)/T6 -> #DIV/0! | AJ6: =(U6-T6)/U6 -> #DIV/0! | AK6: =(V6-U6)/V6 -> #DIV/0! | AL6: =(W6-V6)/W6 -> #DIV/0! | AM6: =(X6-W6)/X6 -> #DIV/0! | AN6: =(Y6-X6)/Y6 -> #DIV/0! | AO6: =(Z6-Y6)/Z6 -> #DIV/0! | AP6: =(AA6-Z6)/AA6 -> #DIV/0! | ... AT6: =(AE6-AD6)/AE6 -> 6.0331825e-05 | AW6: Alamosa County | AX6: =AVERAGE(AH6:AJ6) -> #DIV/0! | AY6: =AVERAGE(AI6:AK6) -> #DIV/0! | AZ6: =AVERAGE(AJ6:AL6) -> #DIV/0! | BA6: =AVERAGE(AK6:AM6) -> #DIV/0! | BB6: =AVERAGE(AL6:AN6) -> #DIV/0! | BC6: =AVERAGE(AM6:AO6) -> #DIV/0! | BD6: =AVERAGE(AN6:AP6) -> #DIV/0! | BE6: =AVERAGE(AO6:AQ6) -> #DIV/0! | ... BH6: =AVERAGE(AR6:AT6) -> #DIV/0!
A7: Arapahoe County | AD7: 816.40208 | AE7: 815.52318 | AG7: Arapahoe County | AH7: =0 -> 0 | AI7: =(T7-S7)/T7 -> #DIV/0! | AJ7: =(U7-T7)/U7 -> #DIV/0! | AK7: =(V7-U7)/V7 -> #DIV/0! | AL7: =(W7-V7)/W7 -> #DIV/0! | AM7: =(X7-W7)/X7 -> #DIV/0! | AN7: =(Y7-X7)/Y7 -> #DIV/0! | AO7: =(Z7-Y7)/Z7 -> #DIV/0! | AP7: =(AA7-Z7)/AA7 -> #DIV/0! | ... AT7: =(AE7-AD7)/AE7 -> -0.0010777193 | AW7: Arapahoe County | AX7: =AVERAGE(AH7:AJ7) -> #DIV/0! | AY7: =AVERAGE(AI7:AK7) -> #DIV/0! | AZ7: =AVERAGE(AJ7:AL7) -> #DIV/0! | BA7: =AVERAGE(AK7:AM7) -> #DIV/0! | BB7: =AVERAGE(AL7:AN7) -> #DIV/0! | BC7: =AVERAGE(AM7:AO7) -> #DIV/0! | BD7: =AVERAGE(AN7:AP7) -> #DIV/0! | BE7: =AVERAGE(AO7:AQ7) -> #DIV/0! | ... BH7: =AVERAGE(AR7:AT7) -> #DIV/0!
A8: Archuleta County | AD8: 10.196895 | AE8: 10.325353 | AG8: Archuleta County | AH8: =0 -> 0 | AI8: =(T8-S8)/T8 -> #DIV/0! | AJ8: =(U8-T8)/U8 -> #DIV/0! | AK8: =(V8-U8)/V8 -> #DIV/0! | AL8: =(W8-V8)/W8 -> #DIV/0! | AM8: =(X8-W8)/X8 -> #DIV/0! | AN8: =(Y8-X8)/Y8 -> #DIV/0! | AO8: =(Z8-Y8)/Z8 -> #DIV/0! | AP8: =(AA8-Z8)/AA8 -> #DIV/0! | ... AT8: =(AE8-AD8)/AE8 -> 0.012441012 | AW8: Archuleta County | AX8: =AVERAGE(AH8:AJ8) -> #DIV/0! | AY8: =AVERAGE(AI8:AK8) -> #DIV/0! | AZ8: =AVERAGE(AJ8:AL8) -> #DIV/0! | BA8: =AVERAGE(AK8:AM8) -> #DIV/0! | BB8: =AVERAGE(AL8:AN8) -> #DIV/0! | BC8: =AVERAGE(AM8:AO8) -> #DIV/0! | BD8: =AVERAGE(AN8:AP8) -> #DIV/0! | BE8: =AVERAGE(AO8:AQ8) -> #DIV/0! | ... BH8: =AVERAGE(AR8:AT8) -> #DIV/0!
A9: Baca County | AD9: 1.364482 | AE9: 1.3410306 | AG9: Baca County | AH9: =0 -> 0 | AI9: =(T9-S9)/T9 -> #DIV/0! | AJ9: =(U9-T9)/U9 -> #DIV/0! | AK9: =(V9-U9)/V9 -> #DIV/0! | AL9: =(W9-V9)/W9 -> #DIV/0! | AM9: =(X9-W9)/X9 -> #DIV/0! | AN9: =(Y9-X9)/Y9 -> #DIV/0! | AO9: =(Z9-Y9)/Z9 -> #DIV/0! | AP9: =(AA9-Z9)/AA9 -> #DIV/0! | ... AT9: =(AE9-AD9)/AE9 -> -0.017487613 | AW9: Baca County | AX9: =AVERAGE(AH9:AJ9) -> #DIV/0! | AY9: =AVERAGE(AI9:AK9) -> #DIV/0! | AZ9: =AVERAGE(AJ9:AL9) -> #DIV/0! | BA9: =AVERAGE(AK9:AM9) -> #DIV/0! | BB9: =AVERAGE(AL9:AN9) -> #DIV/0! | BC9: =AVERAGE(AM9:AO9) -> #DIV/0! | BD9: =AVERAGE(AN9:AP9) -> #DIV/0! | BE9: =AVERAGE(AO9:AQ9) -> #DIV/0! | ... BH9: =AVERAGE(AR9:AT9) -> #DIV/0!
A10: Bent County | AD10: 3.4612315 | AE10: 3.5040589 | AG10: Bent County | AH10: =0 -> 0 | AI10: =(T10-S10)/T10 -> #DIV/0! | AJ10: =(U10-T10)/U10 -> #DIV/0! | AK10: =(V10-U10)/V10 -> #DIV/0! | AL10: =(W10-V10)/W10 -> #DIV/0! | AM10: =(X10-W10)/X10 -> #DIV/0! | AN10: =(Y10-X10)/Y10 -> #DIV/0! | AO10: =(Z10-Y10)/Z10 -> #DIV/0! | AP10: =(AA10-Z10)/AA10 -> #DIV/0! | ... AT10: =(AE10-AD10)/AE10 -> 0.012222222 | AW10: Bent County | AX10: =AVERAGE(AH10:AJ10) -> #DIV/0! | AY10: =AVERAGE(AI10:AK10) -> #DIV/0! | AZ10: =AVERAGE(AJ10:AL10) -> #DIV/0! | BA10: =AVERAGE(AK10:AM10) -> #DIV/0! | BB10: =AVERAGE(AL10:AN10) -> #DIV/0! | BC10: =AVERAGE(AM10:AO10) -> #DIV/0! | BD10: =AVERAGE(AN10:AP10) -> #DIV/0! | BE10: =AVERAGE(AO10:AQ10) -> #DIV/0! | ... BH10: =AVERAGE(AR10:AT10) -> #DIV/0!
A11: Boulder County | AD11: 441.71348 | AE11: 442.17805 | AG11: Boulder County | AH11: =0 -> 0 | AI11: =(T11-S11)/T11 -> #DIV/0! | AJ11: =(U11-T11)/U11 -> #DIV/0! | AK11: =(V11-U11)/V11 -> #DIV/0! | AL11: =(W11-V11)/W11 -> #DIV/0! | AM11: =(X11-W11)/X11 -> #DIV/0! | AN11: =(Y11-X11)/Y11 -> #DIV/0! | AO11: =(Z11-Y11)/Z11 -> #DIV/0! | AP11: =(AA11-Z11)/AA11 -> #DIV/0! | ... AT11: =(AE11-AD11)/AE11 -> 0.0010506255 | AW11: Boulder County | AX11: =AVERAGE(AH11:AJ11) -> #DIV/0! | AY11: =AVERAGE(AI11:AK11) -> #DIV/0! | AZ11: =AVERAGE(AJ11:AL11) -> #DIV/0! | BA11: =AVERAGE(AK11:AM11) -> #DIV/0! | BB11: =AVERAGE(AL11:AN11) -> #DIV/0! | BC11: =AVERAGE(AM11:AO11) -> #DIV/0! | BD11: =AVERAGE(AN11:AP11) -> #DIV/0! | BE11: =AVERAGE(AO11:AQ11) -> #DIV/0! | ... BH11: =AVERAGE(AR11:AT11) -> #DIV/0!
A12: Broomfield County | AD12: 2246.4999 | AE12: 2268.5433 | AG12: Broomfield County | AH12: =0 -> 0 | AI12: =(T12-S12)/T12 -> #DIV/0! | AJ12: =(U12-T12)/U12 -> #DIV/0! | AK12: =(V12-U12)/V12 -> #DIV/0! | AL12: =(W12-V12)/W12 -> #DIV/0! | AM12: =(X12-W12)/X12 -> #DIV/0! | AN12: =(Y12-X12)/Y12 -> #DIV/0! | AO12: =(Z12-Y12)/Z12 -> #DIV/0! | AP12: =(AA12-Z12)/AA12 -> #DIV/0! | ... AT12: =(AE12-AD12)/AE12 -> 0.0097170245 | AW12: Broomfield County | AX12: =AVERAGE(AH12:AJ12) -> #DIV/0! | AY12: =AVERAGE(AI12:AK12) -> #DIV/0! | AZ12: =AVERAGE(AJ12:AL12) -> #DIV/0! | BA12: =AVERAGE(AK12:AM12) -> #DIV/0! | BB12: =AVERAGE(AL12:AN12) -> #DIV/0! | BC12: =AVERAGE(AM12:AO12) -> #DIV/0! | BD12: =AVERAGE(AN12:AP12) -> #DIV/0! | BE12: =AVERAGE(AO12:AQ12) -> #DIV/0! | ... BH12: =AVERAGE(AR12:AT12) -> #DIV/0!
A13: Chaffee County | AD13: 19.462194 | AE13: 19.978898 | AG13: Chaffee County | AH13: =0 -> 0 | AI13: =(T13-S13)/T13 -> #DIV/0! | AJ13: =(U13-T13)/U13 -> #DIV/0! | AK13: =(V13-U13)/V13 -> #DIV/0! | AL13: =(W13-V13)/W13 -> #DIV/0! | AM13: =(X13-W13)/X13 -> #DIV/0! | AN13: =(Y13-X13)/Y13 -> #DIV/0! | AO13: =(Z13-Y13)/Z13 -> #DIV/0! | AP13: =(AA13-Z13)/AA13 -> #DIV/0! | ... AT13: =(AE13-AD13)/AE13 -> 0.025862494 | AW13: Chaffee County | AX13: =AVERAGE(AH13:AJ13) -> #DIV/0! | AY13: =AVERAGE(AI13:AK13) -> #DIV/0! | AZ13: =AVERAGE(AJ13:AL13) -> #DIV/0! | BA13: =AVERAGE(AK13:AM13) -> #DIV/0! | BB13: =AVERAGE(AL13:AN13) -> #DIV/0! | BC13: =AVERAGE(AM13:AO13) -> #DIV/0! | BD13: =AVERAGE(AN13:AP13) -> #DIV/0! | BE13: =AVERAGE(AO13:AQ13) -> #DIV/0! | ... BH13: =AVERAGE(AR13:AT13) -> #DIV/0!
A14: Cheyenne County | AD14: 0.963017 | AE14: 0.9663842 | AG14: Cheyenne County | AH14: =0 -> 0 | AI14: =(T14-S14)/T14 -> #DIV/0! | AJ14: =(U14-T14)/U14 -> #DIV/0! | AK14: =(V14-U14)/V14 -> #DIV/0! | AL14: =(W14-V14)/W14 -> #DIV/0! | AM14: =(X14-W14)/X14 -> #DIV/0! | AN14: =(Y14-X14)/Y14 -> #DIV/0! | AO14: =(Z14-Y14)/Z14 -> #DIV/0! | AP14: =(AA14-Z14)/AA14 -> #DIV/0! | ... AT14: =(AE14-AD14)/AE14 -> 0.0034843206 | AW14: Cheyenne County | AX14: =AVERAGE(AH14:AJ14) -> #DIV/0! | AY14: =AVERAGE(AI14:AK14) -> #DIV/0! | AZ14: =AVERAGE(AJ14:AL14) -> #DIV/0! | BA14: =AVERAGE(AK14:AM14) -> #DIV/0! | BB14: =AVERAGE(AL14:AN14) -> #DIV/0! | BC14: =AVERAGE(AM14:AO14) -> #DIV/0! | BD14: =AVERAGE(AN14:AP14) -> #DIV/0! | BE14: =AVERAGE(AO14:AQ14) -> #DIV/0! | ... BH14: =AVERAGE(AR14:AT14) -> #DIV/0!
A15: Clear Creek County | AD15: 23.849393 | AE15: 23.619903 | AG15: Clear Creek County | AH15: =0 -> 0 | AI15: =(T15-S15)/T15 -> #DIV/0! | AJ15: =(U15-T15)/U15 -> #DIV/0! | AK15: =(V15-U15)/V15 -> #DIV/0! | AL15: =(W15-V15)/W15 -> #DIV/0! | AM15: =(X15-W15)/X15 -> #DIV/0! | AN15: =(Y15-X15)/Y15 -> #DIV/0! | AO15: =(Z15-Y15)/Z15 -> #DIV/0! | AP15: =(AA15-Z15)/AA15 -> #DIV/0! | ... AT15: =(AE15-AD15)/AE15 -> -0.009715994 | AW15: Clear Creek County | AX15: =AVERAGE(AH15:AJ15) -> #DIV/0! | AY15: =AVERAGE(AI15:AK15) -> #DIV/0! | AZ15: =AVERAGE(AJ15:AL15) -> #DIV/0! | BA15: =AVERAGE(AK15:AM15) -> #DIV/0! | BB15: =AVERAGE(AL15:AN15) -> #DIV/0! | BC15: =AVERAGE(AM15:AO15) -> #DIV/0! | BD15: =AVERAGE(AN15:AP15) -> #DIV/0! | BE15: =AVERAGE(AO15:AQ15) -> #DIV/0! | ... BH15: =AVERAGE(AR15:AT15) -> #DIV/0!
A16: Colorado State | AD16: 55.823737 | AE16: 56.089933 | AG16: Colorado State | AI16: =(T16-S16)/T16 -> #DIV/0! | AJ16: =(U16-T16)/U16 -> #DIV/0! | AK16: =(V16-U16)/V16 -> #DIV/0! | AL16: =(W16-V16)/W16 -> #DIV/0! | AM16: =(X16-W16)/X16 -> #DIV/0! | AN16: =(Y16-X16)/Y16 -> #DIV/0! | AO16: =(Z16-Y16)/Z16 -> #DIV/0! | AP16: =(AA16-Z16)/AA16 -> #DIV/0! | ... AT16: =(AE16-AD16)/AE16 -> 0.0047458902 | AW16: Colorado State | AX16: =AVERAGE(AH16:AJ16) -> #DIV/0! | AY16: =AVERAGE(AI16:AK16) -> #DIV/0! | AZ16: =AVERAGE(AJ16:AL16) -> #DIV/0! | BA16: =AVERAGE(AK16:AM16) -> #DIV/0! | BB16: =AVERAGE(AL16:AN16) -> #DIV/0! | BC16: =AVERAGE(AM16:AO16) -> #DIV/0! | BD16: =AVERAGE(AN16:AP16) -> #DIV/0! | BE16: =AVERAGE(AO16:AQ16) -> #DIV/0! | ... BH16: =AVERAGE(AR16:AT16) -> #DIV/0!
A17: Conejos County | AD17: 5.8796174 | AE17: 5.8687666 | AG17: Conejos County | AH17: =0 -> 0 | AI17: =(T17-S17)/T17 -> #DIV/0! | AJ17: =(U17-T17)/U17 -> #DIV/0! | AK17: =(V17-U17)/V17 -> #DIV/0! | AL17: =(W17-V17)/W17 -> #DIV/0! | AM17: =(X17-W17)/X17 -> #DIV/0! | AN17: =(Y17-X17)/Y17 -> #DIV/0! | AO17: =(Z17-Y17)/Z17 -> #DIV/0! | AP17: =(AA17-Z17)/AA17 -> #DIV/0! | ... AT17: =(AE17-AD17)/AE17 -> -0.0018489171 | AW17: Conejos County | AX17: =AVERAGE(AH17:AJ17) -> #DIV/0! | AY17: =AVERAGE(AI17:AK17) -> #DIV/0! | AZ17: =AVERAGE(AJ17:AL17) -> #DIV/0! | BA17: =AVERAGE(AK17:AM17) -> #DIV/0! | BB17: =AVERAGE(AL17:AN17) -> #DIV/0! | BC17: =AVERAGE(AM17:AO17) -> #DIV/0! | BD17: =AVERAGE(AN17:AP17) -> #DIV/0! | BE17: =AVERAGE(AO17:AQ17) -> #DIV/0! | ... BH17: =AVERAGE(AR17:AT17) -> #DIV/0!
A18: Costilla County | AD18: 2.9421334 | AE18: 2.9396932 | AG18: Costilla County | AH18: =0 -> 0 | AI18: =(T18-S18)/T18 -> #DIV/0! | AJ18: =(U18-T18)/U18 -> #DIV/0! | AK18: =(V18-U18)/V18 -> #DIV/0! | AL18: =(W18-V18)/W18 -> #DIV/0! | AM18: =(X18-W18)/X18 -> #DIV/0! | AN18: =(Y18-X18)/Y18 -> #DIV/0! | AO18: =(Z18-Y18)/Z18 -> #DIV/0! | AP18: =(AA18-Z18)/AA18 -> #DIV/0! | ... AT18: =(AE18-AD18)/AE18 -> -0.00083010515 | AW18: Costilla County | AX18: =AVERAGE(AH18:AJ18) -> #DIV/0! | AY18: =AVERAGE(AI18:AK18) -> #DIV/0! | AZ18: =AVERAGE(AJ18:AL18) -> #DIV/0! | BA18: =AVERAGE(AK18:AM18) -> #DIV/0! | BB18: =AVERAGE(AL18:AN18) -> #DIV/0! | BC18: =AVERAGE(AM18:AO18) -> #DIV/0! | BD18: =AVERAGE(AN18:AP18) -> #DIV/0! | BE18: =AVERAGE(AO18:AQ18) -> #DIV/0! | ... BH18: =AVERAGE(AR18:AT18) -> #DIV/0!
A19: Crowley County | AD19: 7.1775776 | AE19: 7.0226299 | AG19: Crowley County | AH19: =0 -> 0 | AI19: =(T19-S19)/T19 -> #DIV/0! | AJ19: =(U19-T19)/U19 -> #DIV/0! | AK19: =(V19-U19)/V19 -> #DIV/0! | AL19: =(W19-V19)/W19 -> #DIV/0! | AM19: =(X19-W19)/X19 -> #DIV/0! | AN19: =(Y19-X19)/Y19 -> #DIV/0! | AO19: =(Z19-Y19)/Z19 -> #DIV/0! | AP19: =(AA19-Z19)/AA19 -> #DIV/0! | ... AT19: =(AE19-AD19)/AE19 -> -0.022064057 | AW19: Crowley County | AX19: =AVERAGE(AH19:AJ19) -> #DIV/0! | AY19: =AVERAGE(AI19:AK19) -> #DIV/0! | AZ19: =AVERAGE(AJ19:AL19) -> #DIV/0! | BA19: =AVERAGE(AK19:AM19) -> #DIV/0! | BB19: =AVERAGE(AL19:AN19) -> #DIV/0! | BC19: =AVERAGE(AM19:AO19) -> #DIV/0! | BD19: =AVERAGE(AN19:AP19) -> #DIV/0! | BE19: =AVERAGE(AO19:AQ19) -> #DIV/0! | ... BH19: =AVERAGE(AR19:AT19) -> #DIV/0!
A20: Custer County | AD20: 6.8502787 | AE20: 7.2209296 | AG20: Custer County | AH20: =0 -> 0 | AI20: =(T20-S20)/T20 -> #DIV/0! | AJ20: =(U20-T20)/U20 -> #DIV/0! | AK20: =(V20-U20)/V20 -> #DIV/0! | AL20: =(W20-V20)/W20 -> #DIV/0! | AM20: =(X20-W20)/X20 -> #DIV/0! | AN20: =(Y20-X20)/Y20 -> #DIV/0! | AO20: =(Z20-Y20)/Z20 -> #DIV/0! | AP20: =(AA20-Z20)/AA20 -> #DIV/0! | ... AT20: =(AE20-AD20)/AE20 -> 0.051330086 | AW20: Custer County | AX20: =AVERAGE(AH20:AJ20) -> #DIV/0! | AY20: =AVERAGE(AI20:AK20) -> #DIV/0! | AZ20: =AVERAGE(AJ20:AL20) -> #DIV/0! | BA20: =AVERAGE(AK20:AM20) -> #DIV/0! | BB20: =AVERAGE(AL20:AN20) -> #DIV/0! | BC20: =AVERAGE(AM20:AO20) -> #DIV/0! | BD20: =AVERAGE(AN20:AP20) -> #DIV/0! | BE20: =AVERAGE(AO20:AQ20) -> #DIV/0! | ... BH20: =AVERAGE(AR20:AT20) -> #DIV/0!
A21: Delta County | AD21: 27.30547 | AE21: 27.475118 | AG21: Delta County | AH21: =0 -> 0 | AI21: =(T21-S21)/T21 -> #DIV/0! | AJ21: =(U21-T21)/U21 -> #DIV/0! | AK21: =(V21-U21)/V21 -> #DIV/0! | AL21: =(W21-V21)/W21 -> #DIV/0! | AM21: =(X21-W21)/X21 -> #DIV/0! | AN21: =(Y21-X21)/Y21 -> #DIV/0! | AO21: =(Z21-Y21)/Z21 -> #DIV/0! | AP21: =(AA21-Z21)/AA21 -> #DIV/0! | ... AT21: =(AE21-AD21)/AE21 -> 0.0061745987 | AW21: Delta County | AX21: =AVERAGE(AH21:AJ21) -> #DIV/0! | AY21: =AVERAGE(AI21:AK21) -> #DIV/0! | AZ21: =AVERAGE(AJ21:AL21) -> #DIV/0! | BA21: =AVERAGE(AK21:AM21) -> #DIV/0! | BB21: =AVERAGE(AL21:AN21) -> #DIV/0! | BC21: =AVERAGE(AM21:AO21) -> #DIV/0! | BD21: =AVERAGE(AN21:AP21) -> #DIV/0! | BE21: =AVERAGE(AO21:AQ21) -> #DIV/0! | ... BH21: =AVERAGE(AR21:AT21) -> #DIV/0!
A22: Denver County | AD22: 4570.0565 | AE22: 4578.1639 | AG22: Denver County | AH22: =0 -> 0 | AI22: =(T22-S22)/T22 -> #DIV/0! | AJ22: =(U22-T22)/U22 -> #DIV/0! | AK22: =(V22-U22)/V22 -> #DIV/0! | AL22: =(W22-V22)/W22 -> #DIV/0! | AM22: =(X22-W22)/X22 -> #DIV/0! | AN22: =(Y22-X22)/Y22 -> #DIV/0! | AO22: =(Z22-Y22)/Z22 -> #DIV/0! | AP22: =(AA22-Z22)/AA22 -> #DIV/0! | ... AT22: =(AE22-AD22)/AE22 -> 0.0017708876 | AW22: Denver County | AX22: =AVERAGE(AH22:AJ22) -> #DIV/0! | AY22: =AVERAGE(AI22:AK22) -> #DIV/0! | AZ22: =AVERAGE(AJ22:AL22) -> #DIV/0! | BA22: =AVERAGE(AK22:AM22) -> #DIV/0! | BB22: =AVERAGE(AL22:AN22) -> #DIV/0! | BC22: =AVERAGE(AM22:AO22) -> #DIV/0! | BD22: =AVERAGE(AN22:AP22) -> #DIV/0! | BE22: =AVERAGE(AO22:AQ22) -> #DIV/0! | ... BH22: =AVERAGE(AR22:AT22) -> #DIV/0!
A23: Dolores County | AD23: 1.9694873 | AE23: 2.0456297 | AG23: Dolores County | AH23: =0 -> 0 | AI23: =(T23-S23)/T23 -> #DIV/0! | AJ23: =(U23-T23)/U23 -> #DIV/0! | AK23: =(V23-U23)/V23 -> #DIV/0! | AL23: =(W23-V23)/W23 -> #DIV/0! | AM23: =(X23-W23)/X23 -> #DIV/0! | AN23: =(Y23-X23)/Y23 -> #DIV/0! | AO23: =(Z23-Y23)/Z23 -> #DIV/0! | AP23: =(AA23-Z23)/AA23 -> #DIV/0! | ... AT23: =(AE23-AD23)/AE23 -> 0.03722197 | AW23: Dolores County | AX23: =AVERAGE(AH23:AJ23) -> #DIV/0! | AY23: =AVERAGE(AI23:AK23) -> #DIV/0! | AZ23: =AVERAGE(AJ23:AL23) -> #DIV/0! | BA23: =AVERAGE(AK23:AM23) -> #DIV/0! | BB23: =AVERAGE(AL23:AN23) -> #DIV/0! | BC23: =AVERAGE(AM23:AO23) -> #DIV/0! | BD23: =AVERAGE(AN23:AP23) -> #DIV/0! | BE23: =AVERAGE(AO23:AQ23) -> #DIV/0! | ... BH23: =AVERAGE(AR23:AT23) -> #DIV/0!
A24: Douglas County | AD24: 438.98611 | AE24: 446.42764 | AG24: Douglas County | AH24: =0 -> 0 | AI24: =(T24-S24)/T24 -> #DIV/0! | AJ24: =(U24-T24)/U24 -> #DIV/0! | AK24: =(V24-U24)/V24 -> #DIV/0! | AL24: =(W24-V24)/W24 -> #DIV/0! | AM24: =(X24-W24)/X24 -> #DIV/0! | AN24: =(Y24-X24)/Y24 -> #DIV/0! | AO24: =(Z24-Y24)/Z24 -> #DIV/0! | AP24: =(AA24-Z24)/AA24 -> #DIV/0! | ... AT24: =(AE24-AD24)/AE24 -> 0.01666906 | AW24: Douglas County | AX24: =AVERAGE(AH24:AJ24) -> #DIV/0! | AY24: =AVERAGE(AI24:AK24) -> #DIV/0! | AZ24: =AVERAGE(AJ24:AL24) -> #DIV/0! | BA24: =AVERAGE(AK24:AM24) -> #DIV/0! | BB24: =AVERAGE(AL24:AN24) -> #DIV/0! | BC24: =AVERAGE(AM24:AO24) -> #DIV/0! | BD24: =AVERAGE(AN24:AP24) -> #DIV/0! | BE24: =AVERAGE(AO24:AQ24) -> #DIV/0! | ... BH24: =AVERAGE(AR24:AT24) -> #DIV/0!
A25: Eagle County | AD25: 32.800042 | AE25: 32.509584 | AG25: Eagle County | AH25: =0 -> 0 | AI25: =(T25-S25)/T25 -> #DIV/0! | AJ25: =(U25-T25)/U25 -> #DIV/0! | AK25: =(V25-U25)/V25 -> #DIV/0! | AL25: =(W25-V25)/W25 -> #DIV/0! | AM25: =(X25-W25)/X25 -> #DIV/0! | AN25: =(Y25-X25)/Y25 -> #DIV/0! | AO25: =(Z25-Y25)/Z25 -> #DIV/0! | AP25: =(AA25-Z25)/AA25 -> #DIV/0! | ... AT25: =(AE25-AD25)/AE25 -> -0.0089345463 | AW25: Eagle County | AX25: =AVERAGE(AH25:AJ25) -> #DIV/0! | AY25: =AVERAGE(AI25:AK25) -> #DIV/0! | AZ25: =AVERAGE(AJ25:AL25) -> #DIV/0! | BA25: =AVERAGE(AK25:AM25) -> #DIV/0! | BB25: =AVERAGE(AL25:AN25) -> #DIV/0! | BC25: =AVERAGE(AM25:AO25) -> #DIV/0! | BD25: =AVERAGE(AN25:AP25) -> #DIV/0! | BE25: =AVERAGE(AO25:AQ25) -> #DIV/0! | ... BH25: =AVERAGE(AR25:AT25) -> #DIV/0!
A26: El Paso County | AD26: 346.33186 | AE26: 347.90567 | AG26: El Paso County | AH26: =0 -> 0 | AI26: =(T26-S26)/T26 -> #DIV/0! | AJ26: =(U26-T26)/U26 -> #DIV/0! | AK26: =(V26-U26)/V26 -> #DIV/0! | AL26: =(W26-V26)/W26 -> #DIV/0! | AM26: =(X26-W26)/X26 -> #DIV/0! | AN26: =(Y26-X26)/Y26 -> #DIV/0! | AO26: =(Z26-Y26)/Z26 -> #DIV/0! | AP26: =(AA26-Z26)/AA26 -> #DIV/0! | ... AT26: =(AE26-AD26)/AE26 -> 0.0045236526 | AW26: El Paso County | AX26: =AVERAGE(AH26:AJ26) -> #DIV/0! | AY26: =AVERAGE(AI26:AK26) -> #DIV/0! | AZ26: =AVERAGE(AJ26:AL26) -> #DIV/0! | BA26: =AVERAGE(AK26:AM26) -> #DIV/0! | BB26: =AVERAGE(AL26:AN26) -> #DIV/0! | BC26: =AVERAGE(AM26:AO26) -> #DIV/0! | BD26: =AVERAGE(AN26:AP26) -> #DIV/0! | BE26: =AVERAGE(AO26:AQ26) -> #DIV/0! | ... BH26: =AVERAGE(AR26:AT26) -> #DIV/0!
A27: Elbert County | AD27: 14.679733 | AE27: 15.045861 | AG27: Elbert County | AH27: =0 -> 0 | AI27: =(T27-S27)/T27 -> #DIV/0! | AJ27: =(U27-T27)/U27 -> #DIV/0! | AK27: =(V27-U27)/V27 -> #DIV/0! | AL27: =(W27-V27)/W27 -> #DIV/0! | AM27: =(X27-W27)/X27 -> #DIV/0! | AN27: =(Y27-X27)/Y27 -> #DIV/0! | AO27: =(Z27-Y27)/Z27 -> #DIV/0! | AP27: =(AA27-Z27)/AA27 -> #DIV/0! | ... AT27: =(AE27-AD27)/AE27 -> 0.024334136 | AW27: Elbert County | AX27: =AVERAGE(AH27:AJ27) -> #DIV/0! | AY27: =AVERAGE(AI27:AK27) -> #DIV/0! | AZ27: =AVERAGE(AJ27:AL27) -> #DIV/0! | BA27: =AVERAGE(AK27:AM27) -> #DIV/0! | BB27: =AVERAGE(AL27:AN27) -> #DIV/0! | BC27: =AVERAGE(AM27:AO27) -> #DIV/0! | BD27: =AVERAGE(AN27:AP27) -> #DIV/0! | BE27: =AVERAGE(AO27:AQ27) -> #DIV/0! | ... BH27: =AVERAGE(AR27:AT27) -> #DIV/0!
A28: Fremont County | AD28: 32.124011 | AE28: 32.333392 | AG28: Fremont County | AH28: =0 -> 0 | AI28: =(T28-S28)/T28 -> #DIV/0! | AJ28: =(U28-T28)/U28 -> #DIV/0! | AK28: =(V28-U28)/V28 -> #DIV/0! | AL28: =(W28-V28)/W28 -> #DIV/0! | AM28: =(X28-W28)/X28 -> #DIV/0! | AN28: =(Y28-X28)/Y28 -> #DIV/0! | AO28: =(Z28-Y28)/Z28 -> #DIV/0! | AP28: =(AA28-Z28)/AA28 -> #DIV/0! | ... AT28: =(AE28-AD28)/AE28 -> 0.0064756909 | AW28: Fremont County | AX28: =AVERAGE(AH28:AJ28) -> #DIV/0! | AY28: =AVERAGE(AI28:AK28) -> #DIV/0! | AZ28: =AVERAGE(AJ28:AL28) -> #DIV/0! | BA28: =AVERAGE(AK28:AM28) -> #DIV/0! | BB28: =AVERAGE(AL28:AN28) -> #DIV/0! | BC28: =AVERAGE(AM28:AO28) -> #DIV/0! | BD28: =AVERAGE(AN28:AP28) -> #DIV/0! | BE28: =AVERAGE(AO28:AQ28) -> #DIV/0! | ... BH28: =AVERAGE(AR28:AT28) -> #DIV/0!
... A69: Yuma County | AD69: 4.191407 | AE69: 4.1863429 | AG69: Yuma County | AH69: =0 -> 0 | AI69: =(T69-S69)/T69 -> #DIV/0! | AJ69: =(U69-T69)/U69 -> #DIV/0! | AK69: =(V69-U69)/V69 -> #DIV/0! | AL69: =(W69-V69)/W69 -> #DIV/0! | AM69: =(X69-W69)/X69 -> #DIV/0! | AN69: =(Y69-X69)/Y69 -> #DIV/0! | AO69: =(Z69-Y69)/Z69 -> #DIV/0! | AP69: =(AA69-Z69)/AA69 -> #DIV/0! | ... AT69: =(AE69-AD69)/AE69 -> -0.0012096774 | AW69: Yuma County | AX69: =AVERAGE(AH69:AJ69) -> #DIV/0! | AY69: =AVERAGE(AI69:AK69) -> #DIV/0! | AZ69: =AVERAGE(AJ69:AL69) -> #DIV/0! | BA69: =AVERAGE(AK69:AM69) -> #DIV/0! | BB69: =AVERAGE(AL69:AN69) -> #DIV/0! | BC69: =AVERAGE(AM69:AO69) -> #DIV/0! | BD69: =AVERAGE(AN69:AP69) -> #DIV/0! | BE69: =AVERAGE(AO69:AQ69) -> #DIV/0! | ... BH69: =AVERAGE(AR69:AT69) -> #DIV/0!
A70: Grand Total | AG70: Grand Total | AH70: =SUM(AH5:AH69) -> 0 | AW70: Grand Total | AX70: =SUM(AX5:AX69) -> #DIV/0!
R72: Absolute Population | AG72: Change in Absolute Population (2010 baseline) | AW72: Change in Population (3-year rolling avg, 2010 baseline)
R73: Row Labels | S73: 2010 | T73: 2011 | U73: 2012 | V73: 2013 | W73: 2014 | X73: 2015 | Y73: 2016 | Z73: 2017 | AA73: 2018 | AB73: 2019 | AC73: 2020 | AD73: 2021 | AE73: 2022 | AG73: Row Labels | AH73: 2010 | AI73: 2011 | AJ73: 2012 | AK73: 2013 | AL73: 2014 | AM73: 2015 | AN73: 2016 | AO73: 2017 | AP73: 2018 | AQ73: 2019 | AR73: 2020 | AS73: 2021 | AT73: 2022 | AW73: Row Labels | AX73: CY 10-12 | AY73: CY 11-13 | AZ73: CY 12-14 | BA73: CY 13-15 | BB73: CY 14-16 | BC73: CY 15-17 | BD73: CY 16-18 | BE73: CY 17-19 | BF73: CY 18-20 | BG73: CY 19-21 | BH73: CY 20-22 | BI73: CY 20-22 - Std Devs | BJ73: >1% Dev | BK73: <- 1% Dev | BL73: Stratum | BQ73: Mean sq | BR73: Var | BS73: Std Dev
R74: Adams County | S74: 443711 | T74: 452181 | U74: 460468 | V74: 469878 | W74: 479901 | X74: 490351 | Y74: 497822 | Z74: 503706 | AA74: 511422 | AB74: 516482 | AC74: 520433 | AD74: 523417 | AE74: 527501 | AG74: Adams County | AH74: 0 | AI74: =(T74-S74)/S74 -> 0.019089002 | AJ74: =(U74-T74)/T74 -> 0.018326732 | AK74: =(V74-U74)/U74 -> 0.020435731 | AL74: =(W74-V74)/V74 -> 0.021331069 | AM74: =(X74-W74)/W74 -> 0.021775324 | AN74: =(Y74-X74)/X74 -> 0.015236025 | AO74: =(Z74-Y74)/Y74 -> 0.011819486 | AP74: =(AA74-Z74)/Z74 -> 0.01531846 | ... AT74: =(AE74-AD74)/AD74 -> 0.0078025742 | AW74: Adams County | AX74: =AVERAGE(AH74:AJ74) -> 0.012471911 | AY74: =AVERAGE(AI74:AK74) -> 0.019283821 | AZ74: =AVERAGE(AJ74:AL74) -> 0.020031177 | BA74: =AVERAGE(AK74:AM74) -> 0.021180708 | BB74: =AVERAGE(AL74:AN74) -> 0.019447473 | BC74: =AVERAGE(AM74:AO74) -> 0.016276945 | BD74: =AVERAGE(AN74:AP74) -> 0.014124657 | BE74: =AVERAGE(AO74:AQ74) -> 0.012343976 | ... BH74: =AVERAGE(AR74:AT74) -> 0.0070620308 | BI74: =(BH74-$BO$78)/$BO$79 -> 0.23425076 | BJ74: =IF(BI74>1,TRUE,FALSE) -> FALSE | BK74: =IF(BI74<-1,TRUE,FALSE) -> FALSE | BL74: =_xlfn.XLOOKUP(AW74,'County Population Strata'!$A$3:$A$66,'County Population Strata'!$P$3:$P$66) -> Medium | BQ74: =POWER(BH74-$BO$78,2) -> 1.0802725e-05 | BR74: =SUM(BQ74:BQ138)/COUNTA(BH74:BH138) -> 0.00019401293 | BS74: =SQRT(BR74) -> 0.013928852
R75: Alamosa County | S75: 15474 | T75: 15528 | U75: 15604 | V75: 15709 | W75: 15788 | X75: 15885 | Y75: 15936 | Z75: 16053 | AA75: 16184 | AB75: 16247 | AC75: 16371 | AD75: 16574 | AE75: 16575 | AG75: Alamosa County | AH75: 0 | AI75: =(T75-S75)/S75 -> 0.0034897247 | AJ75: =(U75-T75)/T75 -> 0.0048943843 | AK75: =(V75-U75)/U75 -> 0.0067290438 | AL75: =(W75-V75)/V75 -> 0.0050289643 | AM75: =(X75-W75)/W75 -> 0.0061439068 | AN75: =(Y75-X75)/X75 -> 0.003210576 | AO75: =(Z75-Y75)/Y75 -> 0.0073418675 | AP75: =(AA75-Z75)/Z75 -> 0.0081604684 | ... AT75: =(AE75-AD75)/AD75 -> 6.0335465e-05 | AW75: Alamosa County | AX75: =AVERAGE(AH75:AJ75) -> 0.002794703 | AY75: =AVERAGE(AI75:AK75) -> 0.0050377176 | AZ75: =AVERAGE(AJ75:AL75) -> 0.0055507975 | BA75: =AVERAGE(AK75:AM75) -> 0.005967305 | BB75: =AVERAGE(AL75:AN75) -> 0.0047944824 | BC75: =AVERAGE(AM75:AO75) -> 0.0055654501 | BD75: =AVERAGE(AN75:AP75) -> 0.0062376373 | BE75: =AVERAGE(AO75:AQ75) -> 0.0064650232 | ... BH75: =AVERAGE(AR75:AT75) -> 0.0066974964 | BI75: =(BH75-$BO$78)/$BO$79 -> 0.20826995 | BJ75: =IF(BI75>1,TRUE,FALSE) -> FALSE | BK75: =IF(BI75<-1,TRUE,FALSE) -> FALSE | BL75: =_xlfn.XLOOKUP(AW75,'County Population Strata'!$A$3:$A$66,'County Population Strata'!$P$3:$P$66) -> Tiny | BN75: Population | BO75: =COUNTA(BH74:BH138) -> 64 | BQ75: =POWER(BH75-$BO$78,2) -> 8.5393441e-06
R76: Arapahoe County | S76: 574819 | T76: 585817 | U76: 596228 | V76: 607861 | W76: 618310 | X76: 629965 | Y76: 637656 | Z76: 642976 | AA76: 650167 | AB76: 653804 | AC76: 655212 | AD76: 656722 | AE76: 656015 | AG76: Arapahoe County | AH76: 0 | AI76: =(T76-S76)/S76 -> 0.019132979 | AJ76: =(U76-T76)/T76 -> 0.017771761 | AK76: =(V76-U76)/U76 -> 0.019510992 | AL76: =(W76-V76)/V76 -> 0.017189785 | AM76: =(X76-W76)/W76 -> 0.018849768 | AN76: =(Y76-X76)/X76 -> 0.012208615 | AO76: =(Z76-Y76)/Y76 -> 0.0083430564 | AP76: =(AA76-Z76)/Z76 -> 0.011183932 | ... AT76: =(AE76-AD76)/AD76 -> -0.001076559 | AW76: Arapahoe County | AX76: =AVERAGE(AH76:AJ76) -> 0.01230158 | AY76: =AVERAGE(AI76:AK76) -> 0.018805244 | AZ76: =AVERAGE(AJ76:AL76) -> 0.018157513 | BA76: =AVERAGE(AK76:AM76) -> 0.018516849 | BB76: =AVERAGE(AL76:AN76) -> 0.016082723 | BC76: =AVERAGE(AM76:AO76) -> 0.013133813 | BD76: =AVERAGE(AN76:AP76) -> 0.010578534 | BE76: =AVERAGE(AO76:AQ76) -> 0.0083736454 | ... BH76: =AVERAGE(AR76:AT76) -> 0.0011271964 | BI76: =(BH76-$BO$78)/$BO$79 -> -0.18873227 | BJ76: =IF(BI76>1,TRUE,FALSE) -> FALSE | BK76: =IF(BI76<-1,TRUE,FALSE) -> FALSE | BL76: =_xlfn.XLOOKUP(AW76,'County Population Strata'!$A$3:$A$66,'County Population Strata'!$P$3:$P$66) -> Large | BN76: Variance | BO76: =BR74 -> 0.00019401293 | BQ76: =POWER(BH76-$BO$78,2) -> 7.0123511e-06
R77: Archuleta County | S77: 12060 | T77: 11955 | U77: 11990 | V77: 11995 | W77: 11931 | X77: 12009 | Y77: 12362 | Z77: 12758 | AA77: 13034 | AB77: 13194 | AC77: 13428 | AD77: 13812 | AE77: 13986 | AG77: Archuleta County | AH77: 0 | AI77: =(T77-S77)/S77 -> -0.0087064677 | AJ77: =(U77-T77)/T77 -> 0.0029276453 | AK77: =(V77-U77)/U77 -> 0.00041701418 | AL77: =(W77-V77)/V77 -> -0.0053355565 | AM77: =(X77-W77)/W77 -> 0.0065375911 | AN77: =(Y77-X77)/X77 -> 0.029394621 | AO77: =(Z77-Y77)/Y77 -> 0.032033652 | AP77: =(AA77-Z77)/Z77 -> 0.021633485 | ... AT77: =(AE77-AD77)/AD77 -> 0.012597741 | AW77: Archuleta County | AX77: =AVERAGE(AH77:AJ77) -> -0.0019262741 | AY77: =AVERAGE(AI77:AK77) -> -0.0017872694 | AZ77: =AVERAGE(AJ77:AL77) -> -0.00066363232 | BA77: =AVERAGE(AK77:AM77) -> 0.00053968295 | BB77: =AVERAGE(AL77:AN77) -> 0.010198885 | BC77: =AVERAGE(AM77:AO77) -> 0.022655288 | BD77: =AVERAGE(AN77:AP77) -> 0.027687252 | BE77: =AVERAGE(AO77:AQ77) -> 0.021980908 | ... BH77: =AVERAGE(AR77:AT77) -> 0.019643346 | BI77: =(BH77-$BO$78)/$BO$79 -> 1.1309367 | BJ77: =IF(BI77>1,TRUE,FALSE) -> TRUE | BK77: =IF(BI77<-1,TRUE,FALSE) -> FALSE | BL77: =_xlfn.XLOOKUP(AW77,'County Population Strata'!$A$3:$A$66,'County Population Strata'!$P$3:$P$66) -> Tiny | BN77: Manual Std. Dev | BO77: =BS74 -> 0.013928852 | BQ77: =POWER(BH77-$BO$78,2) -> 0.00025179548
