Workbook

Sheet README
B2: Dataset | C2: Page Name | D2: Source
B3: County Population and Housing Timeseries, 2010 to Current Year | C3: CountyPopHousing | D3: link
B4: County Population Profiles, 1985 to Current Year | C4: CountingHousingProf | D4: link

Sheet CountyHousingProf
A1: Vintage 2022 prepared October 2023.
A2: countyfips | B2: name | C2: year | D2: totalpopulation | E2: births | F2: naturalincrease | G2: netmigration | H2: deaths | I2: totalhousingunits | J2: households | K2: householdsize | L2: householdpopulation | M2: censusbuildingpermits | N2: vacancyrate | O2: vacanthousingunits | P2: hhldpoptothuratio
A3: 000 | B3: COLORADO STATE | C3: 2020 | D3: 5784584 | E3: 62809 | F3: 20660 | G3: 29011 | H3: 42149 | I3: 2501178 | L3: 5659934 | M3: 40469 | P3: 2.2629073
A4: 001 | B4: ADAMS COUNTY | C4: 2020 | D4: 520433 | E4: 6805 | F4: 3403 | G4: 548 | H4: 3402 | I4: 187288 | L4: 515957 | M4: 4027 | P4: 2.7548855
A5: 003 | B5: ALAMOSA COUNTY | C5: 2020 | D5: 16371 | E5: 187 | F5: 28 | G5: 96 | H5: 159 | I5: 7072 | L5: 15411 | M5: 62 | P5: 2.1791572
A6: 005 | B6: ARAPAHOE COUNTY | C6: 2020 | D6: 655212 | E6: 7580 | F6: 2964 | G6: -1556 | H6: 4616 | I6: 263241 | L6: 649825 | M6: 4116 | P6: 2.4685554
A7: 007 | B7: ARCHULETA COUNTY | C7: 2020 | D7: 13428 | E7: 102 | F7: -8 | G7: 242 | H7: 110 | I7: 9537 | L7: 13330 | M7: 153 | P7: 1.3977142
A8: 009 | B8: BACA COUNTY | C8: 2020 | D8: 3478 | E8: 40 | F8: -28 | G8: -59 | H8: 68 | I8: 1972 | L8: 3424 | M8: 2 | P8: 1.7363083
A9: 011 | B9: BENT COUNTY | C9: 2020 | D9: 5477 | E9: 43 | F9: -28 | G9: -475 | H9: 71 | I9: 2136 | L9: 4071 | M9: 5 | P9: 1.9058989
A10: 013 | B10: BOULDER COUNTY | C10: 2020 | D10: 330923 | E10: 2507 | F10: 467 | G10: 1629 | H10: 2040 | I10: 141291 | L10: 315633 | M10: 1634 | P10: 2.2339215
A11: 014 | B11: BROOMFIELD COUNTY | C11: 2020 | D11: 74494 | E11: 642 | F11: 210 | G11: 1615 | H11: 432 | I11: 31463 | L11: 74013 | M11: 427 | P11: 2.3523822
A12: 015 | B12: CHAFFEE COUNTY | C12: 2020 | D12: 19478 | E12: 135 | F12: -74 | G12: 161 | H12: 209 | I12: 10993 | L12: 18247 | M12: 186 | P12: 1.6598745
A13: 017 | B13: CHEYENNE COUNTY | C13: 2020 | D13: 1744 | E13: 17 | F13: 0 | G13: -33 | H13: 17 | I13: 929 | L13: 1722 | M13: 6 | P13: 1.853606
A14: 019 | B14: CLEAR CREEK COUNTY | C14: 2020 | D14: 9397 | E14: 67 | F14: -6 | G14: -11 | H14: 73 | I14: 5688 | L14: 9315 | M14: 94 | P14: 1.6376582
... A197: 125 | B197: YUMA COUNTY | C197: 2022 | D197: 9920 | E197: 140 | F197: 45 | G197: -57 | H197: 95 | I197: 4326 | L197: 9757 | M197: 20 | P197: 2.2554323

Sheet CountyPopHousing
A1: Vintage 2022 prepared October 2023.
A2: County FIPS | B2: County | C2: Year | D2: Total Population | E2: Household Population | F2: Group Quarters Population | G2: Household Size | H2: Total Housing Units | I2: Occupied Housing Units | J2: Vacant Housing Units | K2: Vacancy Percent | L2: Household Population to Total Housing Units Ratio
A3: 0 | B3: Colorado State | C3: 2010 | D3: 5050332 | E3: 4933380 | F3: 116952 | G3: 2.5 | H3: 2205618 | I3: 1971855 | J3: 233763 | K3: 10.6 | L3: 2.2367337
A4: 1 | B4: Adams County | C4: 2010 | D4: 443711 | E4: 439684 | F4: 4027 | G4: 2.85 | H4: 163435 | I4: 154505 | J4: 8930 | K4: 5.46 | L4: 2.6902683
A5: 3 | B5: Alamosa County | C5: 2010 | D5: 15474 | E5: 14734 | F5: 740 | G5: 2.45 | H5: 6561 | I5: 6007 | J5: 554 | K5: 8.44 | L5: 2.2456943
A6: 5 | B6: Arapahoe County | C6: 2010 | D6: 574819 | E6: 569899 | F6: 4920 | G6: 2.53 | H6: 239171 | I6: 225108 | J6: 14063 | K6: 5.88 | L6: 2.3828098
A7: 7 | B7: Archuleta County | C7: 2010 | D7: 12060 | E7: 11931 | F7: 129 | G7: 2.27 | H7: 8762 | I7: 5257 | J7: 3505 | K7: 40 | L7: 1.3616754
A8: 9 | B8: Baca County | C8: 2010 | D8: 3795 | E8: 3713 | F8: 82 | G8: 2.52 | H8: 1964 | I8: 1475 | J8: 489 | K8: 24.9 | L8: 1.8905295
A9: 11 | B9: Bent County | C9: 2010 | D9: 6506 | E9: 4298 | F9: 2208 | G9: 2.49 | H9: 2111 | I9: 1728 | J9: 383 | K9: 18.14 | L9: 2.0360019
A10: 13 | B10: Boulder County | C10: 2010 | D10: 295605 | E10: 286209 | F10: 9396 | G10: 2.39 | H10: 127213 | I10: 119568 | J10: 7645 | K10: 6.01 | L10: 2.2498408
A11: 14 | B11: Broomfield County | C11: 2010 | D11: 56107 | E11: 55825 | F11: 282 | G11: 2.6 | H11: 22685 | I11: 21498 | J11: 1187 | K11: 5.23 | L11: 2.4608772
A12: 15 | B12: Chaffee County | C12: 2010 | D12: 17797 | E12: 16361 | F12: 1436 | G12: 2.15 | H12: 10030 | I12: 7595 | J12: 2435 | K12: 24.28 | L12: 1.6312064
A13: 17 | B13: Cheyenne County | C13: 2010 | D13: 1834 | E13: 1792 | F13: 42 | G13: 2.55 | H13: 868 | I13: 702 | J13: 166 | K13: 19.12 | L13: 2.0645161
A14: 19 | B14: Clear Creek County | C14: 2010 | D14: 9155 | E14: 9024 | F14: 131 | G14: 2.22 | H14: 5472 | I14: 4060 | J14: 1412 | K14: 25.8 | L14: 1.6491228
... A652: 125 | B652: Yuma County | C652: 2019 | D652: 10010 | E652: 9793 | F652: 217 | G652: 2.54 | H652: 4317 | I652: 3862 | J652: 455 | K652: 10.55 | L652: 2.2684735
A653: 0 | B653: Colorado State | C653: 2020 | D653: 5784584 | E653: 5659934 | F653: 124650 | H653: 2501178 | L653: 2.2629073
A654: 1 | B654: Adams County | C654: 2020 | D654: 520433 | E654: 515957 | F654: 4476 | H654: 187288 | L654: 2.7548855
A655: 3 | B655: Alamosa County | C655: 2020 | D655: 16371 | E655: 15411 | F655: 960 | H655: 7072 | L655: 2.1791572
A656: 5 | B656: Arapahoe County | C656: 2020 | D656: 655212 | E656: 649825 | F656: 5387 | H656: 263241 | L656: 2.4685554
A657: 7 | B657: Archuleta County | C657: 2020 | D657: 13428 | E657: 13330 | F657: 98 | H657: 9537 | L657: 1.3977142
A658: 9 | B658: Baca County | C658: 2020 | D658: 3478 | E658: 3424 | F658: 54 | H658: 1972 | L658: 1.7363083
A659: 11 | B659: Bent County | C659: 2020 | D659: 5477 | E659: 4071 | F659: 1406 | H659: 2136 | L659: 1.9058989
A660: 13 | B660: Boulder County | C660: 2020 | D660: 330923 | E660: 315633 | F660: 15290 | H660: 141291 | L660: 2.2339215
A661: 14 | B661: Broomfield County | C661: 2020 | D661: 74494 | E661: 74013 | F661: 481 | H661: 31463 | L661: 2.3523822
A662: 15 | B662: Chaffee County | C662: 2020 | D662: 19478 | E662: 18247 | F662: 1231 | H662: 10993 | L662: 1.6598745
A663: 17 | B663: Cheyenne County | C663: 2020 | D663: 1744 | E663: 1722 | F663: 22 | H663: 929 | L663: 1.853606
A664: 19 | B664: Clear Creek County | C664: 2020 | D664: 9397 | E664: 9315 | F664: 82 | H664: 5688 | L664: 1.6376582
... A847: 125 | B847: Yuma County | C847: 2022 | D847: 9920 | E847: 9757 | F847: 163 | H847: 4326 | L847: 2.2554323

Sheet Lookups
A1: {=_xlfn.UNIQUE(CountyHousingProf!B2:B197)} -> name | B1: =CountyHousingProf!A2 -> countyfips | C1: area (sq. mi) | D1: region
A2: COLORADO STATE | B2: =_xlfn.XLOOKUP(A2,CountyHousingProf!$B$3:$B$197,CountyHousingProf!$A$3:$A$197) -> 000 | C2: =SUM(C3:C66) -> 104095.97
A3: ADAMS COUNTY | B3: =_xlfn.XLOOKUP(A3,CountyHousingProf!$B$3:$B$197,CountyHousingProf!$A$3:$A$197) -> 001 | C3: 1182.29 | D3: 3
A4: ALAMOSA COUNTY | B4: =_xlfn.XLOOKUP(A4,CountyHousingProf!$B$3:$B$197,CountyHousingProf!$A$3:$A$197) -> 003 | C4: 723.21 | D4: 8
A5: ARAPAHOE COUNTY | B5: =_xlfn.XLOOKUP(A5,CountyHousingProf!$B$3:$B$197,CountyHousingProf!$A$3:$A$197) -> 005 | C5: 804.41 | D5: 3
A6: ARCHULETA COUNTY | B6: =_xlfn.XLOOKUP(A6,CountyHousingProf!$B$3:$B$197,CountyHousingProf!$A$3:$A$197) -> 007 | C6: 1354.53 | D6: 9
A7: BACA COUNTY | B7: =_xlfn.XLOOKUP(A7,CountyHousingProf!$B$3:$B$197,CountyHousingProf!$A$3:$A$197) -> 009 | C7: 2558.48 | D7: 6
A8: BENT COUNTY | B8: =_xlfn.XLOOKUP(A8,CountyHousingProf!$B$3:$B$197,CountyHousingProf!$A$3:$A$197) -> 011 | C8: 1541.07 | D8: 6
A9: BOULDER COUNTY | B9: =_xlfn.XLOOKUP(A9,CountyHousingProf!$B$3:$B$197,CountyHousingProf!$A$3:$A$197) -> 013 | C9: 740.48 | D9: 3
A10: BROOMFIELD COUNTY | B10: =_xlfn.XLOOKUP(A10,CountyHousingProf!$B$3:$B$197,CountyHousingProf!$A$3:$A$197) -> 014 | C10: 33.57 | D10: 3
A11: CHAFFEE COUNTY | B11: =_xlfn.XLOOKUP(A11,CountyHousingProf!$B$3:$B$197,CountyHousingProf!$A$3:$A$197) -> 015 | C11: 1014.12 | D11: 13
A12: CHEYENNE COUNTY | B12: =_xlfn.XLOOKUP(A12,CountyHousingProf!$B$3:$B$197,CountyHousingProf!$A$3:$A$197) -> 017 | C12: 1781.9 | D12: 5
A13: CLEAR CREEK COUNTY | B13: =_xlfn.XLOOKUP(A13,CountyHousingProf!$B$3:$B$197,CountyHousingProf!$A$3:$A$197) -> 019 | C13: 396.53 | D13: 3
A14: CONEJOS COUNTY | B14: =_xlfn.XLOOKUP(A14,CountyHousingProf!$B$3:$B$197,CountyHousingProf!$A$3:$A$197) -> 021 | C14: 1290.22 | D14: 8
... A66: YUMA COUNTY | B66: =_xlfn.XLOOKUP(A66,CountyHousingProf!$B$3:$B$197,CountyHousingProf!$A$3:$A$197) -> 125 | C66: 2369.61 | D66: 1

Sheet COMB_RAW_DATA
A1: County FIPS | B1: Region | C1: County | D1: Year | E1: Total Population | F1: Household Population | G1: Group Quarters Population | H1: Household Size | I1: Total Housing Units | J1: Occupied Housing Units | K1: Vacant Housing Units | L1: Vacancy Percent | M1: Household Population to Total Housing Units Ratio | N1: Density (pers/sq mi) | O1: totalpopulation | P1: births | Q1: naturalincrease | R1: netmigration | S1: deaths | T1: totalhousingunits | U1: households | V1: householdsize | W1: householdpopulation | X1: censusbuildingpermits | Y1: vacancyrate | Z1: vacanthousingunits | AA1: hhldpoptothuratio
A2: 1 | B2: 3 | C2: Adams County | D2: 2010 | E2: 443711 | F2: 439684 | G2: 4027 | H2: 2.85 | I2: 163435 | J2: 154505 | K2: 8930 | L2: 5.46 | M2: 2.6902683 | N2: =E2/_xlfn.XLOOKUP(C2,Lookups!$A$2:$A$66,Lookups!$C$2:$C$66) -> 375.29794
A3: 1 | B3: 3 | C3: Adams County | D3: 2011 | E3: 452181 | F3: 448120 | G3: 4061 | H3: 2.85 | I3: 164593 | J3: 157248 | K3: 7345 | L3: 4.46 | M3: 2.7225945 | N3: =E3/_xlfn.XLOOKUP(C3,Lookups!$A$2:$A$66,Lookups!$C$2:$C$66) -> 382.462
A4: 1 | B4: 3 | C4: Adams County | D4: 2012 | E4: 460468 | F4: 456411 | G4: 4057 | H4: 2.85 | I4: 165858 | J4: 159932 | K4: 5926 | L4: 3.57 | M4: 2.7518178 | N4: =E4/_xlfn.XLOOKUP(C4,Lookups!$A$2:$A$66,Lookups!$C$2:$C$66) -> 389.47128
A5: 1 | B5: 3 | C5: Adams County | D5: 2013 | E5: 469878 | F5: 465792 | G5: 4086 | H5: 2.86 | I5: 167459 | J5: 162991 | K5: 4468 | L5: 2.67 | M5: 2.7815286 | N5: =E5/_xlfn.XLOOKUP(C5,Lookups!$A$2:$A$66,Lookups!$C$2:$C$66) -> 397.43041
A6: 1 | B6: 3 | C6: Adams County | D6: 2014 | E6: 479901 | F6: 475690 | G6: 4211 | H6: 2.86 | I6: 169377 | J6: 166221 | K6: 3156 | L6: 1.86 | M6: 2.8084687 | N6: =E6/_xlfn.XLOOKUP(C6,Lookups!$A$2:$A$66,Lookups!$C$2:$C$66) -> 405.90803
A7: 1 | B7: 3 | C7: Adams County | D7: 2015 | E7: 490351 | F7: 486126 | G7: 4225 | H7: 2.87 | I7: 171361 | J7: 169630 | K7: 1731 | L7: 1.01 | M7: 2.8368532 | N7: =E7/_xlfn.XLOOKUP(C7,Lookups!$A$2:$A$66,Lookups!$C$2:$C$66) -> 414.7468
A8: 1 | B8: 3 | C8: Adams County | D8: 2016 | E8: 497822 | F8: 493406 | G8: 4416 | H8: 2.87 | I8: 173204 | J8: 171930 | K8: 1274 | L8: 0.74 | M8: 2.8486986 | N8: =E8/_xlfn.XLOOKUP(C8,Lookups!$A$2:$A$66,Lookups!$C$2:$C$66) -> 421.0659
A9: 1 | B9: 3 | C9: Adams County | D9: 2017 | E9: 503706 | F9: 499300 | G9: 4406 | H9: 2.87 | I9: 176439 | J9: 173741 | K9: 2698 | L9: 1.53 | M9: 2.8298732 | N9: =E9/_xlfn.XLOOKUP(C9,Lookups!$A$2:$A$66,Lookups!$C$2:$C$66) -> 426.04268
A10: 1 | B10: 3 | C10: Adams County | D10: 2018 | E10: 511422 | F10: 506996 | G10: 4426 | H10: 2.88 | I10: 180056 | J10: 176173 | K10: 3883 | L10: 2.16 | M10: 2.8157684 | N10: =E10/_xlfn.XLOOKUP(C10,Lookups!$A$2:$A$66,Lookups!$C$2:$C$66) -> 432.569
A11: 1 | B11: 3 | C11: Adams County | D11: 2019 | E11: 516482 | F11: 512038 | G11: 4444 | H11: 2.88 | I11: 183751 | J11: 177677 | K11: 6074 | L11: 3.31 | M11: 2.7865862 | N11: =E11/_xlfn.XLOOKUP(C11,Lookups!$A$2:$A$66,Lookups!$C$2:$C$66) -> 436.84883
A12: 1 | B12: 3 | C12: Adams County | D12: 2020 | E12: 520433 | F12: 515957 | G12: 4476 | I12: 187288 | M12: 2.7548855 | N12: =E12/_xlfn.XLOOKUP(C12,Lookups!$A$2:$A$66,Lookups!$C$2:$C$66) -> 440.19065 | O12: 520433 | P12: 6805 | Q12: 3403 | R12: 548 | S12: 3402 | T12: 187288 | W12: 515957 | X12: 4027 | AA12: 2.7548855
A13: 1 | B13: 3 | C13: Adams County | D13: 2021 | E13: 523417 | F13: 518896 | G13: 4521 | I13: 191198 | M13: 2.7139196 | N13: =E13/_xlfn.XLOOKUP(C13,Lookups!$A$2:$A$66,Lookups!$C$2:$C$66) -> 442.71456 | O13: 523417 | P13: 6644 | Q13: 2686 | R13: 298 | S13: 3958 | T13: 191198 | W13: 518896 | X13: 4687 | AA13: 2.7139196
A14: 1 | B14: 3 | C14: Adams County | D14: 2022 | E14: 527501 | F14: 522937 | G14: 4564 | I14: 196741 | M14: 2.6579971 | N14: =E14/_xlfn.XLOOKUP(C14,Lookups!$A$2:$A$66,Lookups!$C$2:$C$66) -> 446.16888 | O14: 527501 | P14: 6838 | Q14: 2544 | R14: 1540 | S14: 4294 | T14: 196741 | W14: 522937 | X14: 2811 | AA14: 2.6579971
A15: 3 | B15: 8 | C15: Alamosa County | D15: 2010 | E15: 15474 | F15: 14734 | G15: 740 | H15: 2.45 | I15: 6561 | J15: 6007 | K15: 554 | L15: 8.44 | M15: 2.2456943 | N15: =E15/_xlfn.XLOOKUP(C15,Lookups!$A$2:$A$66,Lookups!$C$2:$C$66) -> 21.396275
A16: 3 | B16: 8 | C16: Alamosa County | D16: 2011 | E16: 15528 | F16: 14788 | G16: 740 | H16: 2.45 | I16: 6591 | J16: 6037 | K16: 554 | L16: 8.41 | M16: 2.2436656 | N16: =E16/_xlfn.XLOOKUP(C16,Lookups!$A$2:$A$66,Lookups!$C$2:$C$66) -> 21.470942
A17: 3 | B17: 8 | C17: Alamosa County | D17: 2012 | E17: 15604 | F17: 14864 | G17: 740 | H17: 2.45 | I17: 6636 | J17: 6075 | K17: 561 | L17: 8.45 | M17: 2.2399036 | N17: =E17/_xlfn.XLOOKUP(C17,Lookups!$A$2:$A$66,Lookups!$C$2:$C$66) -> 21.576029
A18: 3 | B18: 8 | C18: Alamosa County | D18: 2013 | E18: 15709 | F18: 14969 | G18: 740 | H18: 2.44 | I18: 6700 | J18: 6126 | K18: 574 | L18: 8.57 | M18: 2.2341791 | N18: =E18/_xlfn.XLOOKUP(C18,Lookups!$A$2:$A$66,Lookups!$C$2:$C$66) -> 21.721215
A19: 3 | B19: 8 | C19: Alamosa County | D19: 2014 | E19: 15788 | F19: 14923 | G19: 865 | H19: 2.44 | I19: 6747 | J19: 6115 | K19: 632 | L19: 9.37 | M19: 2.2117978 | N19: =E19/_xlfn.XLOOKUP(C19,Lookups!$A$2:$A$66,Lookups!$C$2:$C$66) -> 21.83045
A20: 3 | B20: 8 | C20: Alamosa County | D20: 2015 | E20: 15885 | F20: 15020 | G20: 865 | H20: 2.44 | I20: 6807 | J20: 6163 | K20: 644 | L20: 9.46 | M20: 2.2065521 | N20: =E20/_xlfn.XLOOKUP(C20,Lookups!$A$2:$A$66,Lookups!$C$2:$C$66) -> 21.964575
A21: 3 | B21: 8 | C21: Alamosa County | D21: 2016 | E21: 15936 | F21: 15071 | G21: 865 | H21: 2.43 | I21: 6835 | J21: 6192 | K21: 643 | L21: 9.41 | M21: 2.2049744 | N21: =E21/_xlfn.XLOOKUP(C21,Lookups!$A$2:$A$66,Lookups!$C$2:$C$66) -> 22.035094
A22: 3 | B22: 8 | C22: Alamosa County | D22: 2017 | E22: 16053 | F22: 15188 | G22: 865 | H22: 2.43 | I22: 6908 | J22: 6247 | K22: 661 | L22: 9.57 | M22: 2.1986103 | N22: =E22/_xlfn.XLOOKUP(C22,Lookups!$A$2:$A$66,Lookups!$C$2:$C$66) -> 22.196872
A23: 3 | B23: 8 | C23: Alamosa County | D23: 2018 | E23: 16184 | F23: 15319 | G23: 865 | H23: 2.43 | I23: 6990 | J23: 6310 | K23: 680 | L23: 9.73 | M23: 2.1915594 | N23: =E23/_xlfn.XLOOKUP(C23,Lookups!$A$2:$A$66,Lookups!$C$2:$C$66) -> 22.378009
A24: 3 | B24: 8 | C24: Alamosa County | D24: 2019 | E24: 16247 | F24: 15382 | G24: 865 | H24: 2.43 | I24: 7026 | J24: 6343 | K24: 683 | L24: 9.72 | M24: 2.1892969 | N24: =E24/_xlfn.XLOOKUP(C24,Lookups!$A$2:$A$66,Lookups!$C$2:$C$66) -> 22.465121
A25: 3 | B25: 8 | C25: Alamosa County | D25: 2020 | E25: 16371 | F25: 15411 | G25: 960 | I25: 7072 | M25: 2.1791572 | N25: =E25/_xlfn.XLOOKUP(C25,Lookups!$A$2:$A$66,Lookups!$C$2:$C$66) -> 22.636579 | O25: 16371 | P25: 187 | Q25: 28 | R25: 96 | S25: 159 | T25: 7072 | W25: 15411 | X25: 62 | AA25: 2.1791572
A26: 3 | B26: 8 | C26: Alamosa County | D26: 2021 | E26: 16574 | F26: 15590 | G26: 984 | I26: 7137 | M26: 2.1843912 | N26: =E26/_xlfn.XLOOKUP(C26,Lookups!$A$2:$A$66,Lookups!$C$2:$C$66) -> 22.917272 | O26: 16574 | P26: 188 | Q26: 26 | R26: 177 | S26: 162 | T26: 7137 | W26: 15590 | X26: 109 | AA26: 2.1843912
A27: 3 | B27: 8 | C27: Alamosa County | D27: 2022 | E27: 16575 | F27: 15609 | G27: 966 | I27: 7250 | M27: 2.1529655 | N27: =E27/_xlfn.XLOOKUP(C27,Lookups!$A$2:$A$66,Lookups!$C$2:$C$66) -> 22.918654 | O27: 16575 | P27: 196 | Q27: -11 | R27: 12 | S27: 207 | T27: 7250 | W27: 15609 | X27: 102 | AA27: 2.1529655
A28: 5 | B28: 3 | C28: Arapahoe County | D28: 2010 | E28: 574819 | F28: 569899 | G28: 4920 | H28: 2.53 | I28: 239171 | J28: 225108 | K28: 14063 | L28: 5.88 | M28: 2.3828098 | N28: =E28/_xlfn.XLOOKUP(C28,Lookups!$A$2:$A$66,Lookups!$C$2:$C$66) -> 714.5846
A29: 5 | B29: 3 | C29: Arapahoe County | D29: 2011 | E29: 585817 | F29: 580907 | G29: 4910 | H29: 2.54 | I29: 240616 | J29: 228868 | K29: 11748 | L29: 4.88 | M29: 2.4142493 | N29: =E29/_xlfn.XLOOKUP(C29,Lookups!$A$2:$A$66,Lookups!$C$2:$C$66) -> 728.25673
A30: 5 | B30: 3 | C30: Arapahoe County | D30: 2012 | E30: 596228 | F30: 591240 | G30: 4988 | H30: 2.54 | I30: 241137 | J30: 232344 | K30: 8793 | L30: 3.65 | M30: 2.4518842 | N30: =E30/_xlfn.XLOOKUP(C30,Lookups!$A$2:$A$66,Lookups!$C$2:$C$66) -> 741.19914
A31: 5 | B31: 3 | C31: Arapahoe County | D31: 2013 | E31: 607861 | F31: 602977 | G31: 4884 | H31: 2.55 | I31: 242604 | J31: 236352 | K31: 6252 | L31: 2.58 | M31: 2.4854372 | N31: =E31/_xlfn.XLOOKUP(C31,Lookups!$A$2:$A$66,Lookups!$C$2:$C$66) -> 755.66067
A32: 5 | B32: 3 | C32: Arapahoe County | D32: 2014 | E32: 618310 | F32: 613335 | G32: 4975 | H32: 2.56 | I32: 245659 | J32: 239801 | K32: 5858 | L32: 2.38 | M32: 2.4966926 | N32: =E32/_xlfn.XLOOKUP(C32,Lookups!$A$2:$A$66,Lookups!$C$2:$C$66) -> 768.65032
A33: 5 | B33: 3 | C33: Arapahoe County | D33: 2015 | E33: 629965 | F33: 625080 | G33: 4885 | H33: 2.56 | I33: 247801 | J33: 243773 | K33: 4028 | L33: 1.63 | M33: 2.522508 | N33: =E33/_xlfn.XLOOKUP(C33,Lookups!$A$2:$A$66,Lookups!$C$2:$C$66) -> 783.1392
A34: 5 | B34: 3 | C34: Arapahoe County | D34: 2016 | E34: 637656 | F34: 632707 | G34: 4949 | H34: 2.57 | I34: 249881 | J34: 246123 | K34: 3758 | L34: 1.5 | M34: 2.5320332 | N34: =E34/_xlfn.XLOOKUP(C34,Lookups!$A$2:$A$66,Lookups!$C$2:$C$66) -> 792.70024
A35: 5 | B35: 3 | C35: Arapahoe County | D35: 2017 | E35: 642976 | F35: 637915 | G35: 5061 | H35: 2.58 | I35: 254352 | J35: 247523 | K35: 6829 | L35: 2.68 | M35: 2.5080007 | N35: =E35/_xlfn.XLOOKUP(C35,Lookups!$A$2:$A$66,Lookups!$C$2:$C$66) -> 799.31378
A36: 5 | B36: 3 | C36: Arapahoe County | D36: 2018 | E36: 650167 | F36: 644993 | G36: 5174 | H36: 2.58 | I36: 257003 | J36: 249640 | K36: 7363 | L36: 2.86 | M36: 2.5096711 | N36: =E36/_xlfn.XLOOKUP(C36,Lookups!$A$2:$A$66,Lookups!$C$2:$C$66) -> 808.25325
A37: 5 | B37: 3 | C37: Arapahoe County | D37: 2019 | E37: 653804 | F37: 648519 | G37: 5285 | H37: 2.59 | I37: 259939 | J37: 250374 | K37: 9565 | L37: 3.68 | M37: 2.4948892 | N37: =E37/_xlfn.XLOOKUP(C37,Lookups!$A$2:$A$66,Lookups!$C$2:$C$66) -> 812.77458
A38: 5 | B38: 3 | C38: Arapahoe County | D38: 2020 | E38: 655212 | F38: 649825 | G38: 5387 | I38: 263241 | M38: 2.4685554 | N38: =E38/_xlfn.XLOOKUP(C38,Lookups!$A$2:$A$66,Lookups!$C$2:$C$66) -> 814.52493 | O38: 655212 | P38: 7580 | Q38: 2964 | R38: -1556 | S38: 4616 | T38: 263241 | W38: 649825 | X38: 4116 | AA38: 2.4685554
A39: 5 | B39: 3 | C39: Arapahoe County | D39: 2021 | E39: 656722 | F39: 651475 | G39: 5247 | I39: 266515 | M39: 2.4444215 | N39: =E39/_xlfn.XLOOKUP(C39,Lookups!$A$2:$A$66,Lookups!$C$2:$C$66) -> 816.40208 | O39: 656722 | P39: 7551 | Q39: 2814 | R39: -1304 | S39: 4737 | T39: 266515 | W39: 651475 | X39: 5519 | AA39: 2.4444215
A40: 5 | B40: 3 | C40: Arapahoe County | D40: 2022 | E40: 656015 | F40: 650714 | G40: 5301 | I40: 270939 | M40: 2.4016993 | N40: =E40/_xlfn.XLOOKUP(C40,Lookups!$A$2:$A$66,Lookups!$C$2:$C$66) -> 815.52318 | O40: 656015 | P40: 7612 | Q40: 2532 | R40: -3239 | S40: 5080 | T40: 270939 | W40: 650714 | X40: 4325 | AA40: 2.4016993
...

Sheet COUNTY_PIVOT
B3: Column Labels | AG3: Change in Population Density (% change year-on-year, 2010 baseline) | AW3: Change in Population Density (3-year rolling avg, 2010 baseline)
A4: Row Labels | B4: 2010 | C4: 2011 | D4: 2012 | E4: 2013 | F4: 2014 | G4: 2015 | H4: 2016 | I4: 2017 | J4: 2018 | K4: 2019 | L4: 2020 | M4: 2021 | N4: 2022 | O4: Grand Total | AD4: 2021 | AE4: 2022 | AG4: Row Labels | AH4: 2010 | AI4: 2011 | AJ4: 2012 | AK4: 2013 | AL4: 2014 | AM4: 2015 | AN4: 2016 | AO4: 2017 | AP4: 2018 | AQ4: 2019 | AR4: 2020 | AS4: 2021 | AT4: 2022 | AW4: Row Labels | AX4: CY 10-12 | AY4: CY 11-13 | AZ4: CY 12-14 | BA4: CY 13-15 | BB4: CY 14-16 | BC4: CY 15-17 | BD4: CY 16-18 | BE4: CY 17-19 | BF4: CY 18-20 | BG4: CY 19-21 | BH4: CY 20-22
A5: Adams County | AD5: 442.71456 | AE5: 446.16888 | AG5: Adams County | AH5: =0 -> 0 | AI5: =(T5-S5)/T5 -> #DIV/0! | AJ5: =(U5-T5)/U5 -> #DIV/0! | AK5: =(V5-U5)/V5 -> #DIV/0! | AL5: =(W5-V5)/W5 -> #DIV/0! | AM5: =(X5-W5)/X5 -> #DIV/0! | AN5: =(Y5-X5)/Y5 -> #DIV/0! | AO5: =(Z5-Y5)/Z5 -> #DIV/0! | AP5: =(AA5-Z5)/AA5 -> #DIV/0! | ... AT5: =(AE5-AD5)/AE5 -> 0.0077421654 | AW5: Adams County | AX5: =AVERAGE(AH5:AJ5) -> #DIV/0! | AY5: =AVERAGE(AI5:AK5) -> #DIV/0! | AZ5: =AVERAGE(AJ5:AL5) -> #DIV/0! | BA5: =AVERAGE(AK5:AM5) -> #DIV/0! | BB5: =AVERAGE(AL5:AN5) -> #DIV/0! | BC5: =AVERAGE(AM5:AO5) -> #DIV/0! | BD5: =AVERAGE(AN5:AP5) -> #DIV/0! | BE5: =AVERAGE(AO5:AQ5) -> #DIV/0! | ... BH5: =AVERAGE(AR5:AT5) -> #DIV/0!
A6: Alamosa County | AD6: 22.917272 | AE6: 22.918654 | AG6: Alamosa County | AH6: =0 -> 0 | AI6: =(T6-S6)/T6 -> #DIV/0! | AJ6: =(U6-T6)/U6 -> #DIV/0! | AK6: =(V6-U6)/V6 -> #DIV/0! | AL6: =(W6-V6)/W6 -> #DIV/0! | AM6: =(X6-W6)/X6 -> #DIV/0! | AN6: =(Y6-X6)/Y6 -> #DIV/0! | AO6: =(Z6-Y6)/Z6 -> #DIV/0! | AP6: =(AA6-Z6)/AA6 -> #DIV/0! | ... AT6: =(AE6-AD6)/AE6 -> 6.0331825e-05 | AW6: Alamosa County | AX6: =AVERAGE(AH6:AJ6) -> #DIV/0! | AY6: =AVERAGE(AI6:AK6) -> #DIV/0! | AZ6: =AVERAGE(AJ6:AL6) -> #DIV/0! | BA6: =AVERAGE(AK6:AM6) -> #DIV/0! | BB6: =AVERAGE(AL6:AN6) -> #DIV/0! | BC6: =AVERAGE(AM6:AO6) -> #DIV/0! | BD6: =AVERAGE(AN6:AP6) -> #DIV/0! | BE6: =AVERAGE(AO6:AQ6) -> #DIV/0! | ... BH6: =AVERAGE(AR6:AT6) -> #DIV/0!
A7: Arapahoe County | AD7: 816.40208 | AE7: 815.52318 | AG7: Arapahoe County | AH7: =0 -> 0 | AI7: =(T7-S7)/T7 -> #DIV/0! | AJ7: =(U7-T7)/U7 -> #DIV/0! | AK7: =(V7-U7)/V7 -> #DIV/0! | AL7: =(W7-V7)/W7 -> #DIV/0! | AM7: =(X7-W7)/X7 -> #DIV/0! | AN7: =(Y7-X7)/Y7 -> #DIV/0! | AO7: =(Z7-Y7)/Z7 -> #DIV/0! | AP7: =(AA7-Z7)/AA7 -> #DIV/0! | ... AT7: =(AE7-AD7)/AE7 -> -0.0010777193 | AW7: Arapahoe County | AX7: =AVERAGE(AH7:AJ7) -> #DIV/0! | AY7: =AVERAGE(AI7:AK7) -> #DIV/0! | AZ7: =AVERAGE(AJ7:AL7) -> #DIV/0! | BA7: =AVERAGE(AK7:AM7) -> #DIV/0! | BB7: =AVERAGE(AL7:AN7) -> #DIV/0! | BC7: =AVERAGE(AM7:AO7) -> #DIV/0! | BD7: =AVERAGE(AN7:AP7) -> #DIV/0! | BE7: =AVERAGE(AO7:AQ7) -> #DIV/0! | ... BH7: =AVERAGE(AR7:AT7) -> #DIV/0!
A8: Archuleta County | AD8: 10.196895 | AE8: 10.325353 | AG8: Archuleta County | AH8: =0 -> 0 | AI8: =(T8-S8)/T8 -> #DIV/0! | AJ8: =(U8-T8)/U8 -> #DIV/0! | AK8: =(V8-U8)/V8 -> #DIV/0! | AL8: =(W8-V8)/W8 -> #DIV/0! | AM8: =(X8-W8)/X8 -> #DIV/0! | AN8: =(Y8-X8)/Y8 -> #DIV/0! | AO8: =(Z8-Y8)/Z8 -> #DIV/0! | AP8: =(AA8-Z8)/AA8 -> #DIV/0! | ... AT8: =(AE8-AD8)/AE8 -> 0.012441012 | AW8: Archuleta County | AX8: =AVERAGE(AH8:AJ8) -> #DIV/0! | AY8: =AVERAGE(AI8:AK8) -> #DIV/0! | AZ8: =AVERAGE(AJ8:AL8) -> #DIV/0! | BA8: =AVERAGE(AK8:AM8) -> #DIV/0! | BB8: =AVERAGE(AL8:AN8) -> #DIV/0! | BC8: =AVERAGE(AM8:AO8) -> #DIV/0! | BD8: =AVERAGE(AN8:AP8) -> #DIV/0! | BE8: =AVERAGE(AO8:AQ8) -> #DIV/0! | ... BH8: =AVERAGE(AR8:AT8) -> #DIV/0!
A9: Baca County | AD9: 1.364482 | AE9: 1.3410306 | AG9: Baca County | AH9: =0 -> 0 | AI9: =(T9-S9)/T9 -> #DIV/0! | AJ9: =(U9-T9)/U9 -> #DIV/0! | AK9: =(V9-U9)/V9 -> #DIV/0! | AL9: =(W9-V9)/W9 -> #DIV/0! | AM9: =(X9-W9)/X9 -> #DIV/0! | AN9: =(Y9-X9)/Y9 -> #DIV/0! | AO9: =(Z9-Y9)/Z9 -> #DIV/0! | AP9: =(AA9-Z9)/AA9 -> #DIV/0! | ... AT9: =(AE9-AD9)/AE9 -> -0.017487613 | AW9: Baca County | AX9: =AVERAGE(AH9:AJ9) -> #DIV/0! | AY9: =AVERAGE(AI9:AK9) -> #DIV/0! | AZ9: =AVERAGE(AJ9:AL9) -> #DIV/0! | BA9: =AVERAGE(AK9:AM9) -> #DIV/0! | BB9: =AVERAGE(AL9:AN9) -> #DIV/0! | BC9: =AVERAGE(AM9:AO9) -> #DIV/0! | BD9: =AVERAGE(AN9:AP9) -> #DIV/0! | BE9: =AVERAGE(AO9:AQ9) -> #DIV/0! | ... BH9: =AVERAGE(AR9:AT9) -> #DIV/0!
A10: Bent County | AD10: 3.4612315 | AE10: 3.5040589 | AG10: Bent County | AH10: =0 -> 0 | AI10: =(T10-S10)/T10 -> #DIV/0! | AJ10: =(U10-T10)/U10 -> #DIV/0! | AK10: =(V10-U10)/V10 -> #DIV/0! | AL10: =(W10-V10)/W10 -> #DIV/0! | AM10: =(X10-W10)/X10 -> #DIV/0! | AN10: =(Y10-X10)/Y10 -> #DIV/0! | AO10: =(Z10-Y10)/Z10 -> #DIV/0! | AP10: =(AA10-Z10)/AA10 -> #DIV/0! | ... AT10: =(AE10-AD10)/AE10 -> 0.012222222 | AW10: Bent County | AX10: =AVERAGE(AH10:AJ10) -> #DIV/0! | AY10: =AVERAGE(AI10:AK10) -> #DIV/0! | AZ10: =AVERAGE(AJ10:AL10) -> #DIV/0! | BA10: =AVERAGE(AK10:AM10) -> #DIV/0! | BB10: =AVERAGE(AL10:AN10) -> #DIV/0! | BC10: =AVERAGE(AM10:AO10) -> #DIV/0! | BD10: =AVERAGE(AN10:AP10) -> #DIV/0! | BE10: =AVERAGE(AO10:AQ10) -> #DIV/0! | ... BH10: =AVERAGE(AR10:AT10) -> #DIV/0!
A11: Boulder County | AD11: 441.71348 | AE11: 442.17805 | AG11: Boulder County | AH11: =0 -> 0 | AI11: =(T11-S11)/T11 -> #DIV/0! | AJ11: =(U11-T11)/U11 -> #DIV/0! | AK11: =(V11-U11)/V11 -> #DIV/0! | AL11: =(W11-V11)/W11 -> #DIV/0! | AM11: =(X11-W11)/X11 -> #DIV/0! | AN11: =(Y11-X11)/Y11 -> #DIV/0! | AO11: =(Z11-Y11)/Z11 -> #DIV/0! | AP11: =(AA11-Z11)/AA11 -> #DIV/0! | ... AT11: =(AE11-AD11)/AE11 -> 0.0010506255 | AW11: Boulder County | AX11: =AVERAGE(AH11:AJ11) -> #DIV/0! | AY11: =AVERAGE(AI11:AK11) -> #DIV/0! | AZ11: =AVERAGE(AJ11:AL11) -> #DIV/0! | BA11: =AVERAGE(AK11:AM11) -> #DIV/0! | BB11: =AVERAGE(AL11:AN11) -> #DIV/0! | BC11: =AVERAGE(AM11:AO11) -> #DIV/0! | BD11: =AVERAGE(AN11:AP11) -> #DIV/0! | BE11: =AVERAGE(AO11:AQ11) -> #DIV/0! | ... BH11: =AVERAGE(AR11:AT11) -> #DIV/0!
A12: Broomfield County | AD12: 2246.4999 | AE12: 2268.5433 | AG12: Broomfield County | AH12: =0 -> 0 | AI12: =(T12-S12)/T12 -> #DIV/0! | AJ12: =(U12-T12)/U12 -> #DIV/0! | AK12: =(V12-U12)/V12 -> #DIV/0! | AL12: =(W12-V12)/W12 -> #DIV/0! | AM12: =(X12-W12)/X12 -> #DIV/0! | AN12: =(Y12-X12)/Y12 -> #DIV/0! | AO12: =(Z12-Y12)/Z12 -> #DIV/0! | AP12: =(AA12-Z12)/AA12 -> #DIV/0! | ... AT12: =(AE12-AD12)/AE12 -> 0.0097170245 | AW12: Broomfield County | AX12: =AVERAGE(AH12:AJ12) -> #DIV/0! | AY12: =AVERAGE(AI12:AK12) -> #DIV/0! | AZ12: =AVERAGE(AJ12:AL12) -> #DIV/0! | BA12: =AVERAGE(AK12:AM12) -> #DIV/0! | BB12: =AVERAGE(AL12:AN12) -> #DIV/0! | BC12: =AVERAGE(AM12:AO12) -> #DIV/0! | BD12: =AVERAGE(AN12:AP12) -> #DIV/0! | BE12: =AVERAGE(AO12:AQ12) -> #DIV/0! | ... BH12: =AVERAGE(AR12:AT12) -> #DIV/0!
A13: Chaffee County | AD13: 19.462194 | AE13: 19.978898 | AG13: Chaffee County | AH13: =0 -> 0 | AI13: =(T13-S13)/T13 -> #DIV/0! | AJ13: =(U13-T13)/U13 -> #DIV/0! | AK13: =(V13-U13)/V13 -> #DIV/0! | AL13: =(W13-V13)/W13 -> #DIV/0! | AM13: =(X13-W13)/X13 -> #DIV/0! | AN13: =(Y13-X13)/Y13 -> #DIV/0! | AO13: =(Z13-Y13)/Z13 -> #DIV/0! | AP13: =(AA13-Z13)/AA13 -> #DIV/0! | ... AT13: =(AE13-AD13)/AE13 -> 0.025862494 | AW13: Chaffee County | AX13: =AVERAGE(AH13:AJ13) -> #DIV/0! | AY13: =AVERAGE(AI13:AK13) -> #DIV/0! | AZ13: =AVERAGE(AJ13:AL13) -> #DIV/0! | BA13: =AVERAGE(AK13:AM13) -> #DIV/0! | BB13: =AVERAGE(AL13:AN13) -> #DIV/0! | BC13: =AVERAGE(AM13:AO13) -> #DIV/0! | BD13: =AVERAGE(AN13:AP13) -> #DIV/0! | BE13: =AVERAGE(AO13:AQ13) -> #DIV/0! | ... BH13: =AVERAGE(AR13:AT13) -> #DIV/0!
A14: Cheyenne County | AD14: 0.963017 | AE14: 0.9663842 | AG14: Cheyenne County | AH14: =0 -> 0 | AI14: =(T14-S14)/T14 -> #DIV/0! | AJ14: =(U14-T14)/U14 -> #DIV/0! | AK14: =(V14-U14)/V14 -> #DIV/0! | AL14: =(W14-V14)/W14 -> #DIV/0! | AM14: =(X14-W14)/X14 -> #DIV/0! | AN14: =(Y14-X14)/Y14 -> #DIV/0! | AO14: =(Z14-Y14)/Z14 -> #DIV/0! | AP14: =(AA14-Z14)/AA14 -> #DIV/0! | ... AT14: =(AE14-AD14)/AE14 -> 0.0034843206 | AW14: Cheyenne County | AX14: =AVERAGE(AH14:AJ14) -> #DIV/0! | AY14: =AVERAGE(AI14:AK14) -> #DIV/0! | AZ14: =AVERAGE(AJ14:AL14) -> #DIV/0! | BA14: =AVERAGE(AK14:AM14) -> #DIV/0! | BB14: =AVERAGE(AL14:AN14) -> #DIV/0! | BC14: =AVERAGE(AM14:AO14) -> #DIV/0! | BD14: =AVERAGE(AN14:AP14) -> #DIV/0! | BE14: =AVERAGE(AO14:AQ14) -> #DIV/0! | ... BH14: =AVERAGE(AR14:AT14) -> #DIV/0!
A15: Clear Creek County | AD15: 23.849393 | AE15: 23.619903 | AG15: Clear Creek County | AH15: =0 -> 0 | AI15: =(T15-S15)/T15 -> #DIV/0! | AJ15: =(U15-T15)/U15 -> #DIV/0! | AK15: =(V15-U15)/V15 -> #DIV/0! | AL15: =(W15-V15)/W15 -> #DIV/0! | AM15: =(X15-W15)/X15 -> #DIV/0! | AN15: =(Y15-X15)/Y15 -> #DIV/0! | AO15: =(Z15-Y15)/Z15 -> #DIV/0! | AP15: =(AA15-Z15)/AA15 -> #DIV/0! | ... AT15: =(AE15-AD15)/AE15 -> -0.009715994 | AW15: Clear Creek County | AX15: =AVERAGE(AH15:AJ15) -> #DIV/0! | AY15: =AVERAGE(AI15:AK15) -> #DIV/0! | AZ15: =AVERAGE(AJ15:AL15) -> #DIV/0! | BA15: =AVERAGE(AK15:AM15) -> #DIV/0! | BB15: =AVERAGE(AL15:AN15) -> #DIV/0! | BC15: =AVERAGE(AM15:AO15) -> #DIV/0! | BD15: =AVERAGE(AN15:AP15) -> #DIV/0! | BE15: =AVERAGE(AO15:AQ15) -> #DIV/0! | ... BH15: =AVERAGE(AR15:AT15) -> #DIV/0!
A16: Colorado State | AD16: 55.823737 | AE16: 56.089933 | AG16: Colorado State | AI16: =(T16-S16)/T16 -> #DIV/0! | AJ16: =(U16-T16)/U16 -> #DIV/0! | AK16: =(V16-U16)/V16 -> #DIV/0! | AL16: =(W16-V16)/W16 -> #DIV/0! | AM16: =(X16-W16)/X16 -> #DIV/0! | AN16: =(Y16-X16)/Y16 -> #DIV/0! | AO16: =(Z16-Y16)/Z16 -> #DIV/0! | AP16: =(AA16-Z16)/AA16 -> #DIV/0! | ... AT16: =(AE16-AD16)/AE16 -> 0.0047458902 | AW16: Colorado State | AX16: =AVERAGE(AH16:AJ16) -> #DIV/0! | AY16: =AVERAGE(AI16:AK16) -> #DIV/0! | AZ16: =AVERAGE(AJ16:AL16) -> #DIV/0! | BA16: =AVERAGE(AK16:AM16) -> #DIV/0! | BB16: =AVERAGE(AL16:AN16) -> #DIV/0! | BC16: =AVERAGE(AM16:AO16) -> #DIV/0! | BD16: =AVERAGE(AN16:AP16) -> #DIV/0! | BE16: =AVERAGE(AO16:AQ16) -> #DIV/0! | ... BH16: =AVERAGE(AR16:AT16) -> #DIV/0!
A17: Conejos County | AD17: 5.8796174 | AE17: 5.8687666 | AG17: Conejos County | AH17: =0 -> 0 | AI17: =(T17-S17)/T17 -> #DIV/0! | AJ17: =(U17-T17)/U17 -> #DIV/0! | AK17: =(V17-U17)/V17 -> #DIV/0! | AL17: =(W17-V17)/W17 -> #DIV/0! | AM17: =(X17-W17)/X17 -> #DIV/0! | AN17: =(Y17-X17)/Y17 -> #DIV/0! | AO17: =(Z17-Y17)/Z17 -> #DIV/0! | AP17: =(AA17-Z17)/AA17 -> #DIV/0! | ... AT17: =(AE17-AD17)/AE17 -> -0.0018489171 | AW17: Conejos County | AX17: =AVERAGE(AH17:AJ17) -> #DIV/0! | AY17: =AVERAGE(AI17:AK17) -> #DIV/0! | AZ17: =AVERAGE(AJ17:AL17) -> #DIV/0! | BA17: =AVERAGE(AK17:AM17) -> #DIV/0! | BB17: =AVERAGE(AL17:AN17) -> #DIV/0! | BC17: =AVERAGE(AM17:AO17) -> #DIV/0! | BD17: =AVERAGE(AN17:AP17) -> #DIV/0! | BE17: =AVERAGE(AO17:AQ17) -> #DIV/0! | ... BH17: =AVERAGE(AR17:AT17) -> #DIV/0!
A18: Costilla County | AD18: 2.9421334 | AE18: 2.9396932 | AG18: Costilla County | AH18: =0 -> 0 | AI18: =(T18-S18)/T18 -> #DIV/0! | AJ18: =(U18-T18)/U18 -> #DIV/0! | AK18: =(V18-U18)/V18 -> #DIV/0! | AL18: =(W18-V18)/W18 -> #DIV/0! | AM18: =(X18-W18)/X18 -> #DIV/0! | AN18: =(Y18-X18)/Y18 -> #DIV/0! | AO18: =(Z18-Y18)/Z18 -> #DIV/0! | AP18: =(AA18-Z18)/AA18 -> #DIV/0! | ... AT18: =(AE18-AD18)/AE18 -> -0.00083010515 | AW18: Costilla County | AX18: =AVERAGE(AH18:AJ18) -> #DIV/0! | AY18: =AVERAGE(AI18:AK18) -> #DIV/0! | AZ18: =AVERAGE(AJ18:AL18) -> #DIV/0! | BA18: =AVERAGE(AK18:AM18) -> #DIV/0! | BB18: =AVERAGE(AL18:AN18) -> #DIV/0! | BC18: =AVERAGE(AM18:AO18) -> #DIV/0! | BD18: =AVERAGE(AN18:AP18) -> #DIV/0! | BE18: =AVERAGE(AO18:AQ18) -> #DIV/0! | ... BH18: =AVERAGE(AR18:AT18) -> #DIV/0!
A19: Crowley County | AD19: 7.1775776 | AE19: 7.0226299 | AG19: Crowley County | AH19: =0 -> 0 | AI19: =(T19-S19)/T19 -> #DIV/0! | AJ19: =(U19-T19)/U19 -> #DIV/0! | AK19: =(V19-U19)/V19 -> #DIV/0! | AL19: =(W19-V19)/W19 -> #DIV/0! | AM19: =(X19-W19)/X19 -> #DIV/0! | AN19: =(Y19-X19)/Y19 -> #DIV/0! | AO19: =(Z19-Y19)/Z19 -> #DIV/0! | AP19: =(AA19-Z19)/AA19 -> #DIV/0! | ... AT19: =(AE19-AD19)/AE19 -> -0.022064057 | AW19: Crowley County | AX19: =AVERAGE(AH19:AJ19) -> #DIV/0! | AY19: =AVERAGE(AI19:AK19) -> #DIV/0! | AZ19: =AVERAGE(AJ19:AL19) -> #DIV/0! | BA19: =AVERAGE(AK19:AM19) -> #DIV/0! | BB19: =AVERAGE(AL19:AN19) -> #DIV/0! | BC19: =AVERAGE(AM19:AO19) -> #DIV/0! | BD19: =AVERAGE(AN19:AP19) -> #DIV/0! | BE19: =AVERAGE(AO19:AQ19) -> #DIV/0! | ... BH19: =AVERAGE(AR19:AT19) -> #DIV/0!
A20: Custer County | AD20: 6.8502787 | AE20: 7.2209296 | AG20: Custer County | AH20: =0 -> 0 | AI20: =(T20-S20)/T20 -> #DIV/0! | AJ20: =(U20-T20)/U20 -> #DIV/0! | AK20: =(V20-U20)/V20 -> #DIV/0! | AL20: =(W20-V20)/W20 -> #DIV/0! | AM20: =(X20-W20)/X20 -> #DIV/0! | AN20: =(Y20-X20)/Y20 -> #DIV/0! | AO20: =(Z20-Y20)/Z20 -> #DIV/0! | AP20: =(AA20-Z20)/AA20 -> #DIV/0! | ... AT20: =(AE20-AD20)/AE20 -> 0.051330086 | AW20: Custer County | AX20: =AVERAGE(AH20:AJ20) -> #DIV/0! | AY20: =AVERAGE(AI20:AK20) -> #DIV/0! | AZ20: =AVERAGE(AJ20:AL20) -> #DIV/0! | BA20: =AVERAGE(AK20:AM20) -> #DIV/0! | BB20: =AVERAGE(AL20:AN20) -> #DIV/0! | BC20: =AVERAGE(AM20:AO20) -> #DIV/0! | BD20: =AVERAGE(AN20:AP20) -> #DIV/0! | BE20: =AVERAGE(AO20:AQ20) -> #DIV/0! | ... BH20: =AVERAGE(AR20:AT20) -> #DIV/0!
A21: Delta County | AD21: 27.30547 | AE21: 27.475118 | AG21: Delta County | AH21: =0 -> 0 | AI21: =(T21-S21)/T21 -> #DIV/0! | AJ21: =(U21-T21)/U21 -> #DIV/0! | AK21: =(V21-U21)/V21 -> #DIV/0! | AL21: =(W21-V21)/W21 -> #DIV/0! | AM21: =(X21-W21)/X21 -> #DIV/0! | AN21: =(Y21-X21)/Y21 -> #DIV/0! | AO21: =(Z21-Y21)/Z21 -> #DIV/0! | AP21: =(AA21-Z21)/AA21 -> #DIV/0! | ... AT21: =(AE21-AD21)/AE21 -> 0.0061745987 | AW21: Delta County | AX21: =AVERAGE(AH21:AJ21) -> #DIV/0! | AY21: =AVERAGE(AI21:AK21) -> #DIV/0! | AZ21: =AVERAGE(AJ21:AL21) -> #DIV/0! | BA21: =AVERAGE(AK21:AM21) -> #DIV/0! | BB21: =AVERAGE(AL21:AN21) -> #DIV/0! | BC21: =AVERAGE(AM21:AO21) -> #DIV/0! | BD21: =AVERAGE(AN21:AP21) -> #DIV/0! | BE21: =AVERAGE(AO21:AQ21) -> #DIV/0! | ... BH21: =AVERAGE(AR21:AT21) -> #DIV/0!
A22: Denver County | AD22: 4570.0565 | AE22: 4578.1639 | AG22: Denver County | AH22: =0 -> 0 | AI22: =(T22-S22)/T22 -> #DIV/0! | AJ22: =(U22-T22)/U22 -> #DIV/0! | AK22: =(V22-U22)/V22 -> #DIV/0! | AL22: =(W22-V22)/W22 -> #DIV/0! | AM22: =(X22-W22)/X22 -> #DIV/0! | AN22: =(Y22-X22)/Y22 -> #DIV/0! | AO22: =(Z22-Y22)/Z22 -> #DIV/0! | AP22: =(AA22-Z22)/AA22 -> #DIV/0! | ... AT22: =(AE22-AD22)/AE22 -> 0.0017708876 | AW22: Denver County | AX22: =AVERAGE(AH22:AJ22) -> #DIV/0! | AY22: =AVERAGE(AI22:AK22) -> #DIV/0! | AZ22: =AVERAGE(AJ22:AL22) -> #DIV/0! | BA22: =AVERAGE(AK22:AM22) -> #DIV/0! | BB22: =AVERAGE(AL22:AN22) -> #DIV/0! | BC22: =AVERAGE(AM22:AO22) -> #DIV/0! | BD22: =AVERAGE(AN22:AP22) -> #DIV/0! | BE22: =AVERAGE(AO22:AQ22) -> #DIV/0! | ... BH22: =AVERAGE(AR22:AT22) -> #DIV/0!
A23: Dolores County | AD23: 1.9694873 | AE23: 2.0456297 | AG23: Dolores County | AH23: =0 -> 0 | AI23: =(T23-S23)/T23 -> #DIV/0! | AJ23: =(U23-T23)/U23 -> #DIV/0! | AK23: =(V23-U23)/V23 -> #DIV/0! | AL23: =(W23-V23)/W23 -> #DIV/0! | AM23: =(X23-W23)/X23 -> #DIV/0! | AN23: =(Y23-X23)/Y23 -> #DIV/0! | AO23: =(Z23-Y23)/Z23 -> #DIV/0! | AP23: =(AA23-Z23)/AA23 -> #DIV/0! | ... AT23: =(AE23-AD23)/AE23 -> 0.03722197 | AW23: Dolores County | AX23: =AVERAGE(AH23:AJ23) -> #DIV/0! | AY23: =AVERAGE(AI23:AK23) -> #DIV/0! | AZ23: =AVERAGE(AJ23:AL23) -> #DIV/0! | BA23: =AVERAGE(AK23:AM23) -> #DIV/0! | BB23: =AVERAGE(AL23:AN23) -> #DIV/0! | BC23: =AVERAGE(AM23:AO23) -> #DIV/0! | BD23: =AVERAGE(AN23:AP23) -> #DIV/0! | BE23: =AVERAGE(AO23:AQ23) -> #DIV/0! | ... BH23: =AVERAGE(AR23:AT23) -> #DIV/0!
A24: Douglas County | AD24: 438.98611 | AE24: 446.42764 | AG24: Douglas County | AH24: =0 -> 0 | AI24: =(T24-S24)/T24 -> #DIV/0! | AJ24: =(U24-T24)/U24 -> #DIV/0! | AK24: =(V24-U24)/V24 -> #DIV/0! | AL24: =(W24-V24)/W24 -> #DIV/0! | AM24: =(X24-W24)/X24 -> #DIV/0! | AN24: =(Y24-X24)/Y24 -> #DIV/0! | AO24: =(Z24-Y24)/Z24 -> #DIV/0! | AP24: =(AA24-Z24)/AA24 -> #DIV/0! | ... AT24: =(AE24-AD24)/AE24 -> 0.01666906 | AW24: Douglas County | AX24: =AVERAGE(AH24:AJ24) -> #DIV/0! | AY24: =AVERAGE(AI24:AK24) -> #DIV/0! | AZ24: =AVERAGE(AJ24:AL24) -> #DIV/0! | BA24: =AVERAGE(AK24:AM24) -> #DIV/0! | BB24: =AVERAGE(AL24:AN24) -> #DIV/0! | BC24: =AVERAGE(AM24:AO24) -> #DIV/0! | BD24: =AVERAGE(AN24:AP24) -> #DIV/0! | BE24: =AVERAGE(AO24:AQ24) -> #DIV/0! | ... BH24: =AVERAGE(AR24:AT24) -> #DIV/0!
A25: Eagle County | AD25: 32.800042 | AE25: 32.509584 | AG25: Eagle County | AH25: =0 -> 0 | AI25: =(T25-S25)/T25 -> #DIV/0! | AJ25: =(U25-T25)/U25 -> #DIV/0! | AK25: =(V25-U25)/V25 -> #DIV/0! | AL25: =(W25-V25)/W25 -> #DIV/0! | AM25: =(X25-W25)/X25 -> #DIV/0! | AN25: =(Y25-X25)/Y25 -> #DIV/0! | AO25: =(Z25-Y25)/Z25 -> #DIV/0! | AP25: =(AA25-Z25)/AA25 -> #DIV/0! | ... AT25: =(AE25-AD25)/AE25 -> -0.0089345463 | AW25: Eagle County | AX25: =AVERAGE(AH25:AJ25) -> #DIV/0! | AY25: =AVERAGE(AI25:AK25) -> #DIV/0! | AZ25: =AVERAGE(AJ25:AL25) -> #DIV/0! | BA25: =AVERAGE(AK25:AM25) -> #DIV/0! | BB25: =AVERAGE(AL25:AN25) -> #DIV/0! | BC25: =AVERAGE(AM25:AO25) -> #DIV/0! | BD25: =AVERAGE(AN25:AP25) -> #DIV/0! | BE25: =AVERAGE(AO25:AQ25) -> #DIV/0! | ... BH25: =AVERAGE(AR25:AT25) -> #DIV/0!
A26: El Paso County | AD26: 346.33186 | AE26: 347.90567 | AG26: El Paso County | AH26: =0 -> 0 | AI26: =(T26-S26)/T26 -> #DIV/0! | AJ26: =(U26-T26)/U26 -> #DIV/0! | AK26: =(V26-U26)/V26 -> #DIV/0! | AL26: =(W26-V26)/W26 -> #DIV/0! | AM26: =(X26-W26)/X26 -> #DIV/0! | AN26: =(Y26-X26)/Y26 -> #DIV/0! | AO26: =(Z26-Y26)/Z26 -> #DIV/0! | AP26: =(AA26-Z26)/AA26 -> #DIV/0! | ... AT26: =(AE26-AD26)/AE26 -> 0.0045236526 | AW26: El Paso County | AX26: =AVERAGE(AH26:AJ26) -> #DIV/0! | AY26: =AVERAGE(AI26:AK26) -> #DIV/0! | AZ26: =AVERAGE(AJ26:AL26) -> #DIV/0! | BA26: =AVERAGE(AK26:AM26) -> #DIV/0! | BB26: =AVERAGE(AL26:AN26) -> #DIV/0! | BC26: =AVERAGE(AM26:AO26) -> #DIV/0! | BD26: =AVERAGE(AN26:AP26) -> #DIV/0! | BE26: =AVERAGE(AO26:AQ26) -> #DIV/0! | ... BH26: =AVERAGE(AR26:AT26) -> #DIV/0!
A27: Elbert County | AD27: 14.679733 | AE27: 15.045861 | AG27: Elbert County | AH27: =0 -> 0 | AI27: =(T27-S27)/T27 -> #DIV/0! | AJ27: =(U27-T27)/U27 -> #DIV/0! | AK27: =(V27-U27)/V27 -> #DIV/0! | AL27: =(W27-V27)/W27 -> #DIV/0! | AM27: =(X27-W27)/X27 -> #DIV/0! | AN27: =(Y27-X27)/Y27 -> #DIV/0! | AO27: =(Z27-Y27)/Z27 -> #DIV/0! | AP27: =(AA27-Z27)/AA27 -> #DIV/0! | ... AT27: =(AE27-AD27)/AE27 -> 0.024334136 | AW27: Elbert County | AX27: =AVERAGE(AH27:AJ27) -> #DIV/0! | AY27: =AVERAGE(AI27:AK27) -> #DIV/0! | AZ27: =AVERAGE(AJ27:AL27) -> #DIV/0! | BA27: =AVERAGE(AK27:AM27) -> #DIV/0! | BB27: =AVERAGE(AL27:AN27) -> #DIV/0! | BC27: =AVERAGE(AM27:AO27) -> #DIV/0! | BD27: =AVERAGE(AN27:AP27) -> #DIV/0! | BE27: =AVERAGE(AO27:AQ27) -> #DIV/0! | ... BH27: =AVERAGE(AR27:AT27) -> #DIV/0!
A28: Fremont County | AD28: 32.124011 | AE28: 32.333392 | AG28: Fremont County | AH28: =0 -> 0 | AI28: =(T28-S28)/T28 -> #DIV/0! | AJ28: =(U28-T28)/U28 -> #DIV/0! | AK28: =(V28-U28)/V28 -> #DIV/0! | AL28: =(W28-V28)/W28 -> #DIV/0! | AM28: =(X28-W28)/X28 -> #DIV/0! | AN28: =(Y28-X28)/Y28 -> #DIV/0! | AO28: =(Z28-Y28)/Z28 -> #DIV/0! | AP28: =(AA28-Z28)/AA28 -> #DIV/0! | ... AT28: =(AE28-AD28)/AE28 -> 0.0064756909 | AW28: Fremont County | AX28: =AVERAGE(AH28:AJ28) -> #DIV/0! | AY28: =AVERAGE(AI28:AK28) -> #DIV/0! | AZ28: =AVERAGE(AJ28:AL28) -> #DIV/0! | BA28: =AVERAGE(AK28:AM28) -> #DIV/0! | BB28: =AVERAGE(AL28:AN28) -> #DIV/0! | BC28: =AVERAGE(AM28:AO28) -> #DIV/0! | BD28: =AVERAGE(AN28:AP28) -> #DIV/0! | BE28: =AVERAGE(AO28:AQ28) -> #DIV/0! | ... BH28: =AVERAGE(AR28:AT28) -> #DIV/0!
... A69: Yuma County | AD69: 4.191407 | AE69: 4.1863429 | AG69: Yuma County | AH69: =0 -> 0 | AI69: =(T69-S69)/T69 -> #DIV/0! | AJ69: =(U69-T69)/U69 -> #DIV/0! | AK69: =(V69-U69)/V69 -> #DIV/0! | AL69: =(W69-V69)/W69 -> #DIV/0! | AM69: =(X69-W69)/X69 -> #DIV/0! | AN69: =(Y69-X69)/Y69 -> #DIV/0! | AO69: =(Z69-Y69)/Z69 -> #DIV/0! | AP69: =(AA69-Z69)/AA69 -> #DIV/0! | ... AT69: =(AE69-AD69)/AE69 -> -0.0012096774 | AW69: Yuma County | AX69: =AVERAGE(AH69:AJ69) -> #DIV/0! | AY69: =AVERAGE(AI69:AK69) -> #DIV/0! | AZ69: =AVERAGE(AJ69:AL69) -> #DIV/0! | BA69: =AVERAGE(AK69:AM69) -> #DIV/0! | BB69: =AVERAGE(AL69:AN69) -> #DIV/0! | BC69: =AVERAGE(AM69:AO69) -> #DIV/0! | BD69: =AVERAGE(AN69:AP69) -> #DIV/0! | BE69: =AVERAGE(AO69:AQ69) -> #DIV/0! | ... BH69: =AVERAGE(AR69:AT69) -> #DIV/0!
A70: Grand Total | AG70: Grand Total | AH70: =SUM(AH5:AH69) -> 0 | AW70: Grand Total | AX70: =SUM(AX5:AX69) -> #DIV/0!
R72: Absolute Population | AG72: Change in Absolute Population (2010 baseline) | AW72: Change in Population (3-year rolling avg, 2010 baseline)
R73: Row Labels | S73: 2010 | T73: 2011 | U73: 2012 | V73: 2013 | W73: 2014 | X73: 2015 | Y73: 2016 | Z73: 2017 | AA73: 2018 | AB73: 2019 | AC73: 2020 | AD73: 2021 | AE73: 2022 | AG73: Row Labels | AH73: 2010 | AI73: 2011 | AJ73: 2012 | AK73: 2013 | AL73: 2014 | AM73: 2015 | AN73: 2016 | AO73: 2017 | AP73: 2018 | AQ73: 2019 | AR73: 2020 | AS73: 2021 | AT73: 2022 | AW73: Row Labels | AX73: CY 10-12 | AY73: CY 11-13 | AZ73: CY 12-14 | BA73: CY 13-15 | BB73: CY 14-16 | BC73: CY 15-17 | BD73: CY 16-18 | BE73: CY 17-19 | BF73: CY 18-20 | BG73: CY 19-21 | BH73: CY 20-22 | BI73: CY 20-22 - Std Devs | BJ73: >1% Dev | BK73: <- 1% Dev | BL73: Stratum | BQ73: Mean sq | BR73: Var | BS73: Std Dev
R74: Adams County | S74: 443711 | T74: 452181 | U74: 460468 | V74: 469878 | W74: 479901 | X74: 490351 | Y74: 497822 | Z74: 503706 | AA74: 511422 | AB74: 516482 | AC74: 520433 | AD74: 523417 | AE74: 527501 | AG74: Adams County | AH74: 0 | AI74: =(T74-S74)/S74 -> 0.019089002 | AJ74: =(U74-T74)/T74 -> 0.018326732 | AK74: =(V74-U74)/U74 -> 0.020435731 | AL74: =(W74-V74)/V74 -> 0.021331069 | AM74: =(X74-W74)/W74 -> 0.021775324 | AN74: =(Y74-X74)/X74 -> 0.015236025 | AO74: =(Z74-Y74)/Y74 -> 0.011819486 | AP74: =(AA74-Z74)/Z74 -> 0.01531846 | ... AT74: =(AE74-AD74)/AD74 -> 0.0078025742 | AW74: Adams County | AX74: =AVERAGE(AH74:AJ74) -> 0.012471911 | AY74: =AVERAGE(AI74:AK74) -> 0.019283821 | AZ74: =AVERAGE(AJ74:AL74) -> 0.020031177 | BA74: =AVERAGE(AK74:AM74) -> 0.021180708 | BB74: =AVERAGE(AL74:AN74) -> 0.019447473 | BC74: =AVERAGE(AM74:AO74) -> 0.016276945 | BD74: =AVERAGE(AN74:AP74) -> 0.014124657 | BE74: =AVERAGE(AO74:AQ74) -> 0.012343976 | ... BH74: =AVERAGE(AR74:AT74) -> 0.0070620308 | BI74: =(BH74-$BO$78)/$BO$79 -> 0.23425076 | BJ74: =IF(BI74>1,TRUE,FALSE) -> FALSE | BK74: =IF(BI74<-1,TRUE,FALSE) -> FALSE | BL74: =_xlfn.XLOOKUP(AW74,'County Population Strata'!$A$3:$A$66,'County Population Strata'!$P$3:$P$66) -> Medium | BQ74: =POWER(BH74-$BO$78,2) -> 1.0802725e-05 | BR74: =SUM(BQ74:BQ138)/COUNTA(BH74:BH138) -> 0.00019401293 | BS74: =SQRT(BR74) -> 0.013928852
R75: Alamosa County | S75: 15474 | T75: 15528 | U75: 15604 | V75: 15709 | W75: 15788 | X75: 15885 | Y75: 15936 | Z75: 16053 | AA75: 16184 | AB75: 16247 | AC75: 16371 | AD75: 16574 | AE75: 16575 | AG75: Alamosa County | AH75: 0 | AI75: =(T75-S75)/S75 -> 0.0034897247 | AJ75: =(U75-T75)/T75 -> 0.0048943843 | AK75: =(V75-U75)/U75 -> 0.0067290438 | AL75: =(W75-V75)/V75 -> 0.0050289643 | AM75: =(X75-W75)/W75 -> 0.0061439068 | AN75: =(Y75-X75)/X75 -> 0.003210576 | AO75: =(Z75-Y75)/Y75 -> 0.0073418675 | AP75: =(AA75-Z75)/Z75 -> 0.0081604684 | ... AT75: =(AE75-AD75)/AD75 -> 6.0335465e-05 | AW75: Alamosa County | AX75: =AVERAGE(AH75:AJ75) -> 0.002794703 | AY75: =AVERAGE(AI75:AK75) -> 0.0050377176 | AZ75: =AVERAGE(AJ75:AL75) -> 0.0055507975 | BA75: =AVERAGE(AK75:AM75) -> 0.005967305 | BB75: =AVERAGE(AL75:AN75) -> 0.0047944824 | BC75: =AVERAGE(AM75:AO75) -> 0.0055654501 | BD75: =AVERAGE(AN75:AP75) -> 0.0062376373 | BE75: =AVERAGE(AO75:AQ75) -> 0.0064650232 | ... BH75: =AVERAGE(AR75:AT75) -> 0.0066974964 | BI75: =(BH75-$BO$78)/$BO$79 -> 0.20826995 | BJ75: =IF(BI75>1,TRUE,FALSE) -> FALSE | BK75: =IF(BI75<-1,TRUE,FALSE) -> FALSE | BL75: =_xlfn.XLOOKUP(AW75,'County Population Strata'!$A$3:$A$66,'County Population Strata'!$P$3:$P$66) -> Tiny | BN75: Population | BO75: =COUNTA(BH74:BH138) -> 64 | BQ75: =POWER(BH75-$BO$78,2) -> 8.5393441e-06
R76: Arapahoe County | S76: 574819 | T76: 585817 | U76: 596228 | V76: 607861 | W76: 618310 | X76: 629965 | Y76: 637656 | Z76: 642976 | AA76: 650167 | AB76: 653804 | AC76: 655212 | AD76: 656722 | AE76: 656015 | AG76: Arapahoe County | AH76: 0 | AI76: =(T76-S76)/S76 -> 0.019132979 | AJ76: =(U76-T76)/T76 -> 0.017771761 | AK76: =(V76-U76)/U76 -> 0.019510992 | AL76: =(W76-V76)/V76 -> 0.017189785 | AM76: =(X76-W76)/W76 -> 0.018849768 | AN76: =(Y76-X76)/X76 -> 0.012208615 | AO76: =(Z76-Y76)/Y76 -> 0.0083430564 | AP76: =(AA76-Z76)/Z76 -> 0.011183932 | ... AT76: =(AE76-AD76)/AD76 -> -0.001076559 | AW76: Arapahoe County | AX76: =AVERAGE(AH76:AJ76) -> 0.01230158 | AY76: =AVERAGE(AI76:AK76) -> 0.018805244 | AZ76: =AVERAGE(AJ76:AL76) -> 0.018157513 | BA76: =AVERAGE(AK76:AM76) -> 0.018516849 | BB76: =AVERAGE(AL76:AN76) -> 0.016082723 | BC76: =AVERAGE(AM76:AO76) -> 0.013133813 | BD76: =AVERAGE(AN76:AP76) -> 0.010578534 | BE76: =AVERAGE(AO76:AQ76) -> 0.0083736454 | ... BH76: =AVERAGE(AR76:AT76) -> 0.0011271964 | BI76: =(BH76-$BO$78)/$BO$79 -> -0.18873227 | BJ76: =IF(BI76>1,TRUE,FALSE) -> FALSE | BK76: =IF(BI76<-1,TRUE,FALSE) -> FALSE | BL76: =_xlfn.XLOOKUP(AW76,'County Population Strata'!$A$3:$A$66,'County Population Strata'!$P$3:$P$66) -> Large | BN76: Variance | BO76: =BR74 -> 0.00019401293 | BQ76: =POWER(BH76-$BO$78,2) -> 7.0123511e-06
R77: Archuleta County | S77: 12060 | T77: 11955 | U77: 11990 | V77: 11995 | W77: 11931 | X77: 12009 | Y77: 12362 | Z77: 12758 | AA77: 13034 | AB77: 13194 | AC77: 13428 | AD77: 13812 | AE77: 13986 | AG77: Archuleta County | AH77: 0 | AI77: =(T77-S77)/S77 -> -0.0087064677 | AJ77: =(U77-T77)/T77 -> 0.0029276453 | AK77: =(V77-U77)/U77 -> 0.00041701418 | AL77: =(W77-V77)/V77 -> -0.0053355565 | AM77: =(X77-W77)/W77 -> 0.0065375911 | AN77: =(Y77-X77)/X77 -> 0.029394621 | AO77: =(Z77-Y77)/Y77 -> 0.032033652 | AP77: =(AA77-Z77)/Z77 -> 0.021633485 | ... AT77: =(AE77-AD77)/AD77 -> 0.012597741 | AW77: Archuleta County | AX77: =AVERAGE(AH77:AJ77) -> -0.0019262741 | AY77: =AVERAGE(AI77:AK77) -> -0.0017872694 | AZ77: =AVERAGE(AJ77:AL77) -> -0.00066363232 | BA77: =AVERAGE(AK77:AM77) -> 0.00053968295 | BB77: =AVERAGE(AL77:AN77) -> 0.010198885 | BC77: =AVERAGE(AM77:AO77) -> 0.022655288 | BD77: =AVERAGE(AN77:AP77) -> 0.027687252 | BE77: =AVERAGE(AO77:AQ77) -> 0.021980908 | ... BH77: =AVERAGE(AR77:AT77) -> 0.019643346 | BI77: =(BH77-$BO$78)/$BO$79 -> 1.1309367 | BJ77: =IF(BI77>1,TRUE,FALSE) -> TRUE | BK77: =IF(BI77<-1,TRUE,FALSE) -> FALSE | BL77: =_xlfn.XLOOKUP(AW77,'County Population Strata'!$A$3:$A$66,'County Population Strata'!$P$3:$P$66) -> Tiny | BN77: Manual Std. Dev | BO77: =BS74 -> 0.013928852 | BQ77: =POWER(BH77-$BO$78,2) -> 0.00025179548
R78: Baca County | S78: 3795 | T78: 3767 | U78: 3704 | V78: 3637 | W78: 3564 | X78: 3530 | Y78: 3505 | Z78: 3523 | AA78: 3550 | AB78: 3565 | AC78: 3478 | AD78: 3491 | AE78: 3431 | AG78: Baca County | AH78: 0 | AI78: =(T78-S78)/S78 -> -0.0073781291 | AJ78: =(U78-T78)/T78 -> -0.016724184 | AK78: =(V78-U78)/U78 -> -0.018088553 | AL78: =(W78-V78)/V78 -> -0.020071487 | AM78: =(X78-W78)/W78 -> -0.0095398429 | AN78: =(Y78-X78)/X78 -> -0.007082153 | AO78: =(Z78-Y78)/Y78 -> 0.0051355207 | AP78: =(AA78-Z78)/Z78 -> 0.0076639228 | ... AT78: =(AE78-AD78)/AD78 -> -0.017187052 | AW78: Baca County | AX78: =AVERAGE(AH78:AJ78) -> -0.0080341043 | AY78: =AVERAGE(AI78:AK78) -> -0.014063622 | AZ78: =AVERAGE(AJ78:AL78) -> -0.018294741 | BA78: =AVERAGE(AK78:AM78) -> -0.015899961 | BB78: =AVERAGE(AL78:AN78) -> -0.012231161 | BC78: =AVERAGE(AM78:AO78) -> -0.0038288251 | BD78: =AVERAGE(AN78:AP78) -> 0.0019057635 | BE78: =AVERAGE(AO78:AQ78) -> 0.0056749319 | ... BH78: =AVERAGE(AR78:AT78) -> -0.012617733 | BI78: =(BH78-$BO$78)/$BO$79 -> -1.1683505 | BJ78: =IF(BI78>1,TRUE,FALSE) -> FALSE | BK78: =IF(BI78<-1,TRUE,FALSE) -> TRUE | BL78: =_xlfn.XLOOKUP(AW78,'County Population Strata'!$A$3:$A$66,'County Population Strata'!$P$3:$P$66) -> Tiny | BN78: Mean | BO78: =AVERAGE(BH74:BH138) -> 0.0037752808 | BQ78: =POWER(BH78-$BO$78,2) -> 0.0002687309
R79: Bent County | S79: 6506 | T79: 6355 | U79: 5864 | V79: 5800 | W79: 5851 | X79: 5966 | Y79: 5753 | Z79: 5968 | AA79: 5984 | AB79: 5980 | AC79: 5477 | AD79: 5334 | AE79: 5400 | AG79: Bent County | AH79: 0 | AI79: =(T79-S79)/S79 -> -0.023209345 | AJ79: =(U79-T79)/T79 -> -0.077261998 | AK79: =(V79-U79)/U79 -> -0.010914052 | AL79: =(W79-V79)/V79 -> 0.0087931034 | AM79: =(X79-W79)/W79 -> 0.01965476 | AN79: =(Y79-X79)/X79 -> -0.035702313 | AO79: =(Z79-Y79)/Y79 -> 0.037371806 | AP79: =(AA79-Z79)/Z79 -> 0.0026809651 | ... AT79: =(AE79-AD79)/AD79 -> 0.012373453 | AW79: Bent County | AX79: =AVERAGE(AH79:AJ79) -> -0.033490448 | AY79: =AVERAGE(AI79:AK79) -> -0.037128465 | AZ79: =AVERAGE(AJ79:AL79) -> -0.026460982 | BA79: =AVERAGE(AK79:AM79) -> 0.0058446038 | BB79: =AVERAGE(AL79:AN79) -> -0.0024181499 | BC79: =AVERAGE(AM79:AO79) -> 0.0071080843 | BD79: =AVERAGE(AN79:AP79) -> 0.0014501527 | BE79: =AVERAGE(AO79:AQ79) -> 0.013128107 | ... BH79: =AVERAGE(AR79:AT79) -> -0.032616481 | BI79: =(BH79-$BO$78)/$BO$79 -> -2.5936862 | BJ79: =IF(BI79>1,TRUE,FALSE) -> FALSE | BK79: =IF(BI79<-1,TRUE,FALSE) -> TRUE | BL79: =_xlfn.XLOOKUP(AW79,'County Population Strata'!$A$3:$A$66,'County Population Strata'!$P$3:$P$66) -> Tiny | BN79: Excel Std Dev | BO79: =STDEV(BH74:BH138) -> 0.014030904 | BQ79: =POWER(BH79-$BO$78,2) -> 0.0013243603
R80: Boulder County | S80: 295605 | T80: 300526 | U80: 305881 | V80: 310896 | W80: 314213 | X80: 320352 | Y80: 323957 | Z80: 325414 | AA80: 328055 | AB80: 328827 | AC80: 330923 | AD80: 327080 | AE80: 327424 | AG80: Boulder County | AH80: 0 | AI80: =(T80-S80)/S80 -> 0.016647215 | AJ80: =(U80-T80)/T80 -> 0.017818758 | AK80: =(V80-U80)/U80 -> 0.016395265 | AL80: =(W80-V80)/V80 -> 0.010669163 | AM80: =(X80-W80)/W80 -> 0.019537702 | AN80: =(Y80-X80)/X80 -> 0.011253246 | AO80: =(Z80-Y80)/Y80 -> 0.0044975105 | AP80: =(AA80-Z80)/Z80 -> 0.0081158155 | ... AT80: =(AE80-AD80)/AD80 -> 0.0010517305 | AW80: Boulder County | AX80: =AVERAGE(AH80:AJ80) -> 0.011488658 | AY80: =AVERAGE(AI80:AK80) -> 0.016953746 | AZ80: =AVERAGE(AJ80:AL80) -> 0.014961062 | BA80: =AVERAGE(AK80:AM80) -> 0.015534043 | BB80: =AVERAGE(AL80:AN80) -> 0.013820037 | BC80: =AVERAGE(AM80:AO80) -> 0.01176282 | BD80: =AVERAGE(AN80:AP80) -> 0.0079555241 | BE80: =AVERAGE(AO80:AQ80) -> 0.0049888633 | ... BH80: =AVERAGE(AR80:AT80) -> -0.0013956902 | BI80: =(BH80-$BO$78)/$BO$79 -> -0.36854154 | BJ80: =IF(BI80>1,TRUE,FALSE) -> FALSE | BK80: =IF(BI80<-1,TRUE,FALSE) -> FALSE | BL80: =_xlfn.XLOOKUP(AW80,'County Population Strata'!$A$3:$A$66,'County Population Strata'!$P$3:$P$66) -> Small | BN80: CV | BO80: =BO79/BO83 -> 3.6923432 | BQ80: =POWER(BH80-$BO$78,2) -> 2.6738941e-05
R81: Broomfield County | S81: 56107 | T81: 57584 | U81: 59271 | V81: 60669 | W81: 62504 | X81: 65831 | Y81: 67707 | Z81: 69655 | AA81: 71322 | AB81: 72669 | AC81: 74494 | AD81: 75415 | AE81: 76155 | AG81: Broomfield County | AH81: 0 | AI81: =(T81-S81)/S81 -> 0.026324701 | AJ81: =(U81-T81)/T81 -> 0.029296332 | AK81: =(V81-U81)/U81 -> 0.023586577 | AL81: =(W81-V81)/V81 -> 0.030246089 | AM81: =(X81-W81)/W81 -> 0.053228593 | AN81: =(Y81-X81)/X81 -> 0.028497213 | AO81: =(Z81-Y81)/Y81 -> 0.028771028 | AP81: =(AA81-Z81)/Z81 -> 0.023932237 | ... AT81: =(AE81-AD81)/AD81 -> 0.0098123715 | AW81: Broomfield County | AX81: =AVERAGE(AH81:AJ81) -> 0.018540344 | AY81: =AVERAGE(AI81:AK81) -> 0.026402537 | AZ81: =AVERAGE(AJ81:AL81) -> 0.027709666 | BA81: =AVERAGE(AK81:AM81) -> 0.035687087 | BB81: =AVERAGE(AL81:AN81) -> 0.037323965 | BC81: =AVERAGE(AM81:AO81) -> 0.036832278 | BD81: =AVERAGE(AN81:AP81) -> 0.027066826 | BE81: =AVERAGE(AO81:AQ81) -> 0.023863148 | ... BH81: =AVERAGE(AR81:AT81) -> 0.015763219 | BI81: =(BH81-$BO$78)/$BO$79 -> 0.85439525 | BJ81: =IF(BI81>1,TRUE,FALSE) -> FALSE | BK81: =IF(BI81<-1,TRUE,FALSE) -> FALSE | BL81: =_xlfn.XLOOKUP(AW81,'County Population Strata'!$A$3:$A$66,'County Population Strata'!$P$3:$P$66) -> Small | BQ81: =POWER(BH81-$BO$78,2) -> 0.00014371065
R82: Chaffee County | S82: 17797 | T82: 17932 | U82: 17967 | V82: 18036 | W82: 18066 | X82: 18108 | Y82: 18519 | Z82: 18967 | AA82: 19250 | AB82: 19391 | AC82: 19478 | AD82: 19737 | AE82: 20261 | AG82: Chaffee County | AH82: 0 | AI82: =(T82-S82)/S82 -> 0.0075855481 | AJ82: =(U82-T82)/T82 -> 0.001951818 | AK82: =(V82-U82)/U82 -> 0.003840374 | AL82: =(W82-V82)/V82 -> 0.00166334 | AM82: =(X82-W82)/W82 -> 0.002324809 | AN82: =(Y82-X82)/X82 -> 0.02269715 | AO82: =(Z82-Y82)/Y82 -> 0.024191371 | AP82: =(AA82-Z82)/Z82 -> 0.014920652 | ... AT82: =(AE82-AD82)/AD82 -> 0.026549121 | AW82: Chaffee County | AX82: =AVERAGE(AH82:AJ82) -> 0.003179122 | AY82: =AVERAGE(AI82:AK82) -> 0.0044592467 | AZ82: =AVERAGE(AJ82:AL82) -> 0.0024851773 | BA82: =AVERAGE(AK82:AM82) -> 0.0026095077 | BB82: =AVERAGE(AL82:AN82) -> 0.0088950998 | BC82: =AVERAGE(AM82:AO82) -> 0.016404443 | BD82: =AVERAGE(AN82:AP82) -> 0.020603058 | BE82: =AVERAGE(AO82:AQ82) -> 0.015478899 | ... BH82: =AVERAGE(AR82:AT82) -> 0.014777597 | BI82: =(BH82-$BO$78)/$BO$79 -> 0.78414879 | BJ82: =IF(BI82>1,TRUE,FALSE) -> FALSE | BK82: =IF(BI82<-1,TRUE,FALSE) -> FALSE | BL82: =_xlfn.XLOOKUP(AW82,'County Population Strata'!$A$3:$A$66,'County Population Strata'!$P$3:$P$66) -> Small | BQ82: =POWER(BH82-$BO$78,2) -> 0.00012105097
R83: Cheyenne County | S83: 1834 | T83: 1832 | U83: 1832 | V83: 1818 | W83: 1817 | X83: 1806 | Y83: 1794 | Z83: 1788 | AA83: 1783 | AB83: 1777 | AC83: 1744 | AD83: 1716 | AE83: 1722 | AG83: Cheyenne County | AH83: 0 | AI83: =(T83-S83)/S83 -> -0.0010905125 | AJ83: =(U83-T83)/T83 -> 0 | AK83: =(V83-U83)/U83 -> -0.0076419214 | AL83: =(W83-V83)/V83 -> -0.00055005501 | AM83: =(X83-W83)/W83 -> -0.0060539351 | AN83: =(Y83-X83)/X83 -> -0.0066445183 | AO83: =(Z83-Y83)/Y83 -> -0.0033444816 | AP83: =(AA83-Z83)/Z83 -> -0.0027964206 | ... AT83: =(AE83-AD83)/AD83 -> 0.0034965035 | AW83: Cheyenne County | AX83: =AVERAGE(AH83:AJ83) -> -0.00036350418 | AY83: =AVERAGE(AI83:AK83) -> -0.0029108113 | AZ83: =AVERAGE(AJ83:AL83) -> -0.0027306588 | BA83: =AVERAGE(AK83:AM83) -> -0.0047486372 | BB83: =AVERAGE(AL83:AN83) -> -0.0044161694 | BC83: =AVERAGE(AM83:AO83) -> -0.005347645 | BD83: =AVERAGE(AN83:AP83) -> -0.0042618068 | BE83: =AVERAGE(AO83:AQ83) -> -0.0031686724 | ... BH83: =AVERAGE(AR83:AT83) -> -0.010376389 | BI83: =(BH83-$BO$78)/$BO$79 -> -1.0086071 | BJ83: =IF(BI83>1,TRUE,FALSE) -> FALSE | BK83: =IF(BI83<-1,TRUE,FALSE) -> TRUE | BL83: =_xlfn.XLOOKUP(AW83,'County Population Strata'!$A$3:$A$66,'County Population Strata'!$P$3:$P$66) -> Tiny | BO83: 0.0038 | BQ83: =POWER(BH83-$BO$78,2) -> 0.00020026976
...

Sheet County Population Strata
A1: Relative Population (% of total) | N1: Abs. Population | O1: Rel. Population | S1: 2022 Data
A2: Row Labels | B2: 2010 | C2: 2011 | D2: 2012 | E2: 2013 | F2: 2014 | G2: 2015 | H2: 2016 | I2: 2017 | J2: 2018 | K2: 2019 | L2: 2020 | M2: 2021 | N2: 2022 | O2: 2022 | P2: Stratum | S2: Strata | T2: n | U2: Sum | V2: Normalized Weight | W2: Stratum Definition
A3: Hinsdale County | B3: 0.00016691972 | C3: 0.00016297284 | D3: 0.00015997191 | E3: 0.00015652026 | F3: 0.00015315124 | G3: 0.0001492676 | H3: 0.00014630271 | I3: 0.00014376058 | J3: 0.00014109784 | K3: 0.00013914781 | L3: 0.00013691564 | M3: 0.00013388341 | N3: 779 | O3: 0.00013341929 | P3: Tiny | S3: Large | T3: =COUNTIF($P$3:$P$66,S3) -> 3 | U3: =SUMIF($P$3:$P$66,S3,$N$3:$N$66) -> 2109204 | V3: =U3/$N$67 -> 0.36124326 | W3: Any county that comprises >10% of state's population
A4: San Juan County | B4: 0.00014038681 | C4: 0.000137795 | D4: 0.00013533123 | E4: 0.00013356396 | F4: 0.0001308985 | G4: 0.00012778628 | H4: 0.00012604819 | I4: 0.0001250092 | J4: 0.00012383493 | K4: 0.00012293133 | L4: 0.0001229129 | M4: 0.00012751621 | N4: 801 | O4: 0.00013718723 | P4: Tiny | S4: Medium | T4: =COUNTIF($P$3:$P$66,S4) -> 5 | U4: =SUMIF($P$3:$P$66,S4,$N$3:$N$66) -> 2196512 | V4: =U4/$N$67 -> 0.37619649 | W4: Any county that comprises 6-10% of state's population
A5: Mineral County | B5: 0.00013959478 | C5: 0.00013896607 | D5: 0.00013918134 | E5: 0.0001392556 | F5: 0.0001396874 | G5: 0.00013861874 | H5: 0.0001392498 | I5: 0.00014072464 | J5: 0.00014285936 | K5: 0.00014542515 | L5: 0.00015057263 | M5: 0.00015935224 | N5: 924 | O5: 0.00015825343 | P5: Tiny | S5: Small | T5: =COUNTIF($P$3:$P$66,S5) -> 18 | U5: =SUMIF($P$3:$P$66,S5,$N$3:$N$66) -> 1235661 | V5: =U5/$N$67 -> 0.21163159 | W5: Any county that comprises 3.5-6% of state's population
A6: Jackson County | B6: 0.00027463541 | C6: 0.00027071058 | D6: 0.00026661985 | E6: 0.00026238488 | F6: 0.00025824403 | G6: 0.00025355295 | H6: 0.00024938373 | I6: 0.00024626812 | J6: 0.00024291375 | K6: 0.00024045717 | L6: 0.00023821938 | M6: 0.00023369367 | N6: 1314 | O6: 0.00022504871 | P6: Tiny | S6: Tiny | T6: =COUNTIF($P$3:$P$66,S6) -> 38 | U6: =SUMIF($P$3:$P$66,S6,$N$3:$N$66) -> 297359 | V6: =U6/$N$67 -> 0.05092866 | W6: Any county that comprises <3.5% of state's population
A7: Kiowa County | B7: 0.00027701149 | C7: 0.00026992987 | D7: 0.00026796739 | E7: 0.00026504098 | F7: 0.00026048801 | G7: 0.00025814298 | H7: 0.00025679833 | I7: 0.00025501876 | J7: 0.00025401134 | K7: 0.00025370934 | L7: 0.00025135775 | M7: 0.0002500419 | N7: 1428 | O7: 0.00024457348 | P7: Tiny
A8: Cheyenne County | B8: 0.00036314444 | C8: 0.00035756437 | D8: 0.00035266972 | E8: 0.00034491375 | F8: 0.0003397751 | G8: 0.00033158337 | H8: 0.00032443395 | I8: 0.00031930921 | J8: 0.0003140792 | K8: 0.0003098567 | L8: 0.000301491 | M8: 0.00029530069 | N8: 1722 | O8: 0.00029492685 | P8: Tiny
A9: Dolores County | B9: 0.00040789398 | C9: 0.00040304062 | D9: 0.00040002603 | E9: 0.00039500023 | F9: 0.00038970352 | G9: 0.00038317525 | H9: 0.00037760205 | I9: 0.00037288458 | J9: 0.00036833405 | K9: 0.00036356287 | L9: 0.00035923067 | M9: 0.00036499579 | N9: 2203 | O9: 0.00037730769 | P9: Tiny
A10: Sedgwick County | B10: 0.00046868206 | C10: 0.0004627648 | D10: 0.0004572001 | E10: 0.00045134753 | F10: 0.00044580288 | G10: 0.00043843914 | H10: 0.00043257859 | I10: 0.00042788862 | J10: 0.0004229412 | K10: 0.00041936149 | L10: 0.00041334001 | M10: 0.0004009619 | N10: 2297 | O10: 0.00039340707 | P10: Tiny
A11: Baca County | B11: 0.00075143575 | C11: 0.00073523198 | D11: 0.00071303965 | E11: 0.00069001721 | F11: 0.00066646035 | G11: 0.00064811146 | H11: 0.00063385785 | I11: 0.00062915343 | J11: 0.00062533997 | K11: 0.00062163149 | L11: 0.00060125326 | M11: 0.0006007545 | N11: 3431 | O11: 0.00058762719 | P11: Tiny
A12: Costilla County | B12: 0.00069935996 | C12: 0.00068663289 | D12: 0.00067704116 | E12: 0.00066706091 | F12: 0.00065748445 | G12: 0.00064554105 | H12: 0.00063584713 | I12: 0.00062790334 | J12: 0.00061917465 | K12: 0.00061047176 | L12: 0.00060557509 | M12: 0.00062243741 | N12: 3614 | O12: 0.00061896959 | P12: Tiny
A13: Phillips County | B13: 0.00088410029 | C13: 0.00087302698 | D13: 0.00086280878 | E13: 0.00085109079 | F13: 0.00084036835 | G13: 0.00082602081 | H13: 0.00081470174 | I13: 0.00080613074 | J13: 0.00079532676 | K13: 0.00078832986 | L13: 0.00078190584 | M13: 0.00077404575 | N13: 4435 | O13: 0.00075958221 | P13: Tiny
A14: Washington County | B14: 0.00095340267 | C14: 0.00089937588 | D14: 0.0008778242 | E14: 0.00087537515 | F14: 0.00086336908 | G14: 0.00085961979 | H14: 0.00085810427 | I14: 0.00086524223 | J14: 0.00084764393 | K14: 0.00084151292 | L14: 0.00083169334 | M14: 0.00083806199 | N14: 4835 | O14: 0.00082809019 | P14: Tiny
A15: Ouray County | B15: 0.00088033816 | C15: 0.00085955976 | D15: 0.00086203876 | E15: 0.00085659272 | F15: 0.00084672628 | G15: 0.00083538446 | H15: 0.00085376402 | I15: 0.000844705 | J15: 0.00083425637 | K15: 0.00085214953 | L15: 0.00084293011 | M15: 0.00086920967 | N15: 5088 | O15: 0.00087142149 | P15: Tiny
A16: Custer County | B16: 0.00084588498 | C16: 0.00084277454 | D16: 0.00084067067 | E16: 0.00083572335 | F16: 0.00082970947 | G16: 0.00082014558 | H16: 0.00081307415 | I16: 0.00081059535 | J16: 0.00080871432 | K16: 0.00081012619 | L16: 0.00081596187 | M16: 0.0008714468 | N16: 5338 | O16: 0.00091423897 | P16: Tiny
A17: Bent County | B17: 0.0012882321 | C17: 0.0012403502 | D17: 0.0011288511 | E17: 0.0011003849 | F17: 0.0010941244 | G17: 0.0010953635 | H17: 0.0010403949 | I17: 0.0010657927 | J17: 0.0010540942 | K17: 0.0010427367 | L17: 0.00094682695 | M17: 0.00091791019 | N17: 5400 | O17: 0.00092485771 | P17: Tiny
A18: Lincoln County | B18: 0.0010838891 | C18: 0.0010711317 | D18: 0.0010593567 | E18: 0.0010476423 | F18: 0.0010355941 | G18: 0.0010195362 | H18: 0.001007843 | I18: 0.00099846632 | J18: 0.00099015098 | K18: 0.00098379939 | L18: 0.0009788085 | M18: 0.00094131398 | N18: 5513 | O18: 0.00094421121 | P18: Tiny
